Workbook
Name Dash_Comp_Men: 'Dashboard Completo'!$B$36:$K$65
Name Dash_Gral_Men: 'Dashboard General'!$B$31:$M$55
Name SegmentaciónDeDatos_Calendario: #N/A
Name SegmentaciónDeDatos_Calendario1: #N/A
Name SegmentaciónDeDatos_Calendario2: #N/A

Sheet EDT vieja
B1: N1 | C1: N2 | D1: N3 | E1: N4 | F1: Dur. | G1: Comienzo | H1: Fin | I1: Dura. | J1: Pesos | K1: Aporte | M1: Calendario
B2: Proyecto: Plan Master Tacoa | F2: 231 | G2: 45474 | H2: 45835 | I2: 2680 | J2: 1 | K2: 1 | M2: 45474
C3: Actividades Preliminares | F3: 231 | G3: 45474 | H3: 45835 | I3: 87 | J3: 1e-145 | K3: =J3*J2 -> 1e-145 | M3: =M2+7 -> 45481
D4: 0.0 Actividades preliminares | F4: 231 | G4: 45474 | H4: 45835 | I4: 87 | J4: 1 | K4: =J4*J3 -> 1e-145 | M4: =M3+7 -> 45488
E5: Inicio de actividades | F5: 0 | G5: 45474 | H5: 45474 | I5: 0 | J5: 1e-119 | K5: =$K$4*J5 -> 1e-264 | M5: =M4+7 -> 45495
E6: Fin de actividades | F6: 0 | G6: 45835 | H6: 45835 | I6: 0 | J6: 1e-119 | K6: =$K$4*J6 -> 1e-264 | M6: =M5+7 -> 45502
E7: Movilizacion | F7: 25 | G7: 45474 | H7: 45510 | I7: 25 | J7: 0.28735632 | K7: =$K$4*J7 -> 2.8735632e-146 | M7: =M6+7 -> 45509
E8: Preparacion del campamento | F8: 22 | G8: 45474 | H8: 45505 | I8: 22 | J8: 0.25287356 | K8: =$K$4*J8 -> 2.5287356e-146 | M8: =M7+7 -> 45516
E9: Limpieza de áreas y adecuación de plataformas de acceso | F9: 40 | G9: 45482 | H9: 45538 | I9: 40 | J9: 0.45977011 | K9: =$K$4*J9 -> 4.5977011e-146 | M9: =M8+7 -> 45523
C10: Mantenimiento del Generador de Vapor (Caldera) y Equipos Auxiliares | F10: 217 | G10: 45489 | H10: 45828 | I10: 1775 | J10: 0.77282549 | K10: =J10*J2 -> 0.77282549 | M10: =M9+7 -> 45530
D11: 0.0 Actividades preliminares | F11: 55 | G11: 45489 | H11: 45566 | I11: 75 | J11: 0.02 | K11: =J11*$J$10 -> 0.01545651 | M11: =M10+7 -> 45537
E12: Inspecciones visuales externas e internas | F12: 20 | G12: 45489 | H12: 45517 | I12: 20 | J12: 0.26666667 | K12: =J12*$K$11 -> 0.004121736 | M12: =M11+7 -> 45544
E13: Reparación de caminerias, grating, escaleras corroidas | F13: 55 | G13: 45489 | H13: 45566 | I13: 55 | J13: 0.73333333 | K13: =J13*$K$11 -> 0.011334774 | M13: =M12+7 -> 45551
D14: 1.1 Reparación de expansiones metálicas | F14: 105 | G14: 45489 | H14: 45636 | I14: 195 | J14: 0.20327658 | K14: =J14*$J$10 -> 0.15709733 | M14: =M13+7 -> 45558
E15: Procura de laminas de acero al carbono | F15: 10 | G15: 45518 | H15: 45531 | I15: 10 | J15: 0.05 | K15: =J15*$K$14 -> 0.0078548663 | M15: =M14+7 -> 45565
E16: Fabricación en taller de expansiones | F16: 40 | G16: 45532 | H16: 45587 | I16: 40 | J16: 0.08 | K16: =J16*$K$14 -> 0.012567786 | M16: =M15+7 -> 45572
E17: Remoción de expansiones deterioradas | F17: 40 | G17: 45489 | H17: 45545 | I17: 40 | J17: 0.2 | K17: =J17*$K$14 -> 0.031419465 | M17: =M16+7 -> 45579
E18: Instalación de expansiones nuevas | F18: 35 | G18: 45560 | H18: 45608 | I18: 35 | J18: 0.4 | K18: =J18*$K$14 -> 0.06283893 | M18: =M17+7 -> 45586
E19: Galvanizado de expansiones fabricadas | F19: 35 | G19: 45574 | H19: 45622 | I19: 35 | J19: 0.12 | K19: =J19*$K$14 -> 0.018851679 | M19: =M18+7 -> 45593
E20: Instalación de aislamiento y enchaquetado aluminio | F20: 35 | G20: 45588 | H20: 45636 | I20: 35 | J20: 0.15 | K20: =J20*$K$14 -> 0.023564599 | M20: =M19+7 -> 45600
D21: 1.2 Reemplazo de tubos de gas | F21: 60 | G21: 45539 | H21: 45622 | I21: 60 | J21: 0.062393862 | K21: =J21*$J$10 -> 0.048219567 | M21: =M20+7 -> 45607
E22: Reemplazo de tubos de gas de los quemdores de la caldera | F22: 60 | G22: 45539 | H22: 45622 | I22: 60 | J22: 1 | K22: =J22*$K$21 -> 0.048219567 | M22: =M21+7 -> 45614
D23: 1.3 Reparación envoltura metálica | F23: 183 | G23: 45489 | H23: 45782 | I23: 320 | J23: 0.1250084 | K23: =J23*$J$10 -> 0.096609682 | M23: =M22+7 -> 45621
E24: Procura de laminas acanaladas cerramientos exteriores | F24: 30 | G24: 45518 | H24: 45559 | I24: 30 | J24: 0.05 | K24: =J24*$K$23 -> 0.0048304841 | M24: =M23+7 -> 45628
E25: Desmontaje de envoltura metálica externa en paredes | F25: 55 | G25: 45489 | H25: 45566 | I25: 55 | J25: 0.21 | K25: =J25*$K$23 -> 0.020288033 | M25: =M24+7 -> 45635
E26: Desmontaje de lana mineral | F26: 55 | G26: 45504 | H26: 45580 | I26: 55 | J26: 0.14 | K26: =J26*$K$23 -> 0.013525355 | M26: =M25+7 -> 45642
E27: Montaje y ajuste de envoltura metálica externa en paredes | F27: 40 | G27: 45670 | H27: 45727 | I27: 40 | J27: 0.3 | K27: =J27*$K$23 -> 0.028982905 | M27: =M26+7 -> 45649
E28: Aplicación sistema de recubrimiento a envoltura metálica | F28: 55 | G28: 45698 | H28: 45782 | I28: 55 | J28: 0.1 | K28: =J28*$K$23 -> 0.0096609682 | M28: =M27+7 -> 45656
E29: Reemplazo de laminas acanaladas del piso N° 3. Techo de quemadores, lado este y oeste y techo de ventiladores | F29: 55 | G29: 45602 | H29: 45706 | I29: 55 | J29: 0.1 | K29: =J29*$K$23 -> 0.0096609682 | M29: =M28+7 -> 45663
E30: Instalación de laminas de acero estriadas de 1/8" en piso Nº 3 lado este y oeste | F30: 30 | G30: 45581 | H30: 45622 | I30: 30 | J30: 0.1 | K30: =J30*$K$23 -> 0.0096609682 | M30: =M29+7 -> 45670
D31: 1.4 Reparación de cámaras muertas | F31: 75 | G31: 45607 | H31: 45741 | I31: 75 | J31: 0.07022068 | K31: =J31*$J$10 -> 0.054268332 | M31: =M30+7 -> 45677
E32: Reparación de cámara muerta superior | F32: 25 | G32: 45607 | H32: 45639 | I32: 25 | J32: 0.4 | K32: =J32*$K$31 -> 0.021707333 | M32: =M31+7 -> 45684
E33: Reparación de cámara muerta intermedia | F33: 25 | G33: 45670 | H33: 45702 | I33: 25 | J33: 0.4 | K33: =J33*$K$31 -> 0.021707333 | M33: =M32+7 -> 45691
E34: Reparación de cámara muerta inferior | F34: 25 | G34: 45705 | H34: 45741 | I34: 25 | J34: 0.2 | K34: =J34*$K$31 -> 0.010853666 | M34: =M33+7 -> 45698
D35: 1.5 Reparación ductos de aire y gas | F35: 90 | G35: 45574 | H35: 45729 | I35: 80 | J35: 0.20241067 | K35: =J35*$J$10 -> 0.15642813 | M35: =M34+7 -> 45705
E36: Reconstrucción de ductos de entrada de aire | F36: 40 | G36: 45672 | H36: 45729 | I36: 40 | J36: 0.66666667 | K36: =J36*$K$35 -> 0.10428542 | M36: =M35+7 -> 45712
E37: Reconstrucción de ductos aire caliente | F37: 40 | G37: 45574 | H37: 45629 | I37: 40 | J37: 0.33333333 | K37: =J37*$K$35 -> 0.052142709 | M37: =M36+7 -> 45719
D38: 1.6 Reemplazo de tuberías acido y soda | F38: 40 | G38: 45702 | H38: 45762 | I38: 40 | J38: 0.038913409 | K38: =J38*$J$10 -> 0.030073274 | M38: =M37+7 -> 45726
E39: Instalación de tuberías y válvulas de PVC | J39: 1 | K39: =EDT[[#This Row],[Pesos]]*$K$38 -> 0.030073274 | M39: =M38+7 -> 45733
D40: 1.7 Mantenimiento en los equipos de balance BOP y equipos | F40: 120 | G40: 45611 | H40: 45814 | I40: 190 | J40: 0.051069782 | K40: =J40*$J$10 -> 0.03946803 | M40: =M39+7 -> 45740
...

Sheet EDT Nueva
B4: N1 | C4: N2 | D4: N3 | E4: N4 | F4: Nuevos Pesos | G4: Aporte Nuevo
B5: Proyecto: Plan Master Tacoa | F5: 1 | G5: 1
C6: Mantenimiento del Generador de Vapor (Caldera) y Equipos Auxiliares | F6: 0.77282549 | G6: =EDTN[[#This Row],[Nuevos Pesos]]*$G$5 -> 0.77282549
D7: 1.1 Reparación de expansiones metálicas | F7: 0.22602491 | G7: =EDTN[[#This Row],[Nuevos Pesos]]*$G$6 -> 0.17467781
E8: Remoción de expansiones deterioradas | F8: 0.22988506 | G8: =EDTN[[#This Row],[Nuevos Pesos]]*$G$7 -> 0.040155819
E9: Instalación de expansiones nuevas | F9: 0.45977011 | G9: =EDTN[[#This Row],[Nuevos Pesos]]*$G$7 -> 0.080311639
E10: Galvanizado de expansiones fabricadas | F10: 0.13793103 | G10: =EDTN[[#This Row],[Nuevos Pesos]]*$G$7 -> 0.024093492
E11: Instalación de aislamiento y enchaquetado aluminio | F11: 0.17241379 | G11: =EDTN[[#This Row],[Nuevos Pesos]]*$G$7 -> 0.030116865
D12: 1.2 Reemplazo de tubos de gas | F12: 0.069376251 | G12: =EDTN[[#This Row],[Nuevos Pesos]]*$G$6 -> 0.053615736
E13: Reemplazo de tubos de gas de los quemdores de la caldera | F13: 1 | G13: =EDTN[[#This Row],[Nuevos Pesos]]*G12 -> 0.053615736
D14: 1.3 Reparación envoltura metálica | F14: 0.13899788 | G14: =EDTN[[#This Row],[Nuevos Pesos]]*$G$6 -> 0.1074211
E15: Montaje y ajuste de envoltura metálica externa en paredes | F15: 0.75 | G15: =EDTN[[#This Row],[Nuevos Pesos]]*$G$14 -> 0.080565828
E16: Montaje y ajuste de lana mineral externa en paredes | F16: 0.25 | G16: =EDTN[[#This Row],[Nuevos Pesos]]*$G$14 -> 0.026855276
D17: 1.4 Reparación de cámaras muertas | F17: 0.078078954 | G17: =EDTN[[#This Row],[Nuevos Pesos]]*$G$6 -> 0.060341407
E18: Reparación de cámara muerta superior | F18: 0.4 | G18: =EDTN[[#This Row],[Nuevos Pesos]]*$G$17 -> 0.024136563
E19: Reparación de cámara muerta intermedia | F19: 0.4 | G19: =EDTN[[#This Row],[Nuevos Pesos]]*$G$17 -> 0.024136563
E20: Reparación de cámara muerta inferior | F20: 0.2 | G20: =EDTN[[#This Row],[Nuevos Pesos]]*$G$17 -> 0.012068281
D21: 1.5 Reparación ductos de aire y gas | F21: 0.2250621 | G21: =EDTN[[#This Row],[Nuevos Pesos]]*$G$6 -> 0.17393373
E22: Reconstrucción de ductos de entrada de aire | F22: 0.66666667 | G22: =EDTN[[#This Row],[Nuevos Pesos]]*$G$21 -> 0.11595582
E23: Reconstrucción de ductos aire caliente | F23: 0.33333333 | G23: =EDTN[[#This Row],[Nuevos Pesos]]*$G$21 -> 0.057977909
D24: 1.6 Reemplazo de tuberías ácido y soda | F24: 0.056784913 | G24: =EDTN[[#This Row],[Nuevos Pesos]]*$G$6 -> 0.043884828
E25: Instalación de tuberías y válvulas de PVC | F25: 1 | G25: =EDTN[[#This Row],[Nuevos Pesos]]*G24 -> 0.043884828
D26: 1.7 Mantenimiento en los equipos de balance BOP y equipos | F26: 0.056784913 | G26: =EDTN[[#This Row],[Nuevos Pesos]]*$G$6 -> 0.043884828
E27: Servicio de mantenimiento de bombas extracción de condensando | F27: 0.33333333 | G27: =EDTN[[#This Row],[Nuevos Pesos]]*$G$26 -> 0.014628276
E28: Servicio de mantenimiento mantenimiento valvula check de la bomba agua de alimentación | F28: 0.26666667 | G28: =EDTN[[#This Row],[Nuevos Pesos]]*$G$26 -> 0.011702621
E29: Servicio de mantenimiento mantenimiento bombas agua de componentes | F29: 0.4 | G29: =EDTN[[#This Row],[Nuevos Pesos]]*$G$26 -> 0.017553931
D30: 1.9 Matenimiento de equipos y sistema de instrumentación | F30: 0.10418706 | G30: =EDTN[[#This Row],[Nuevos Pesos]]*$G$6 -> 0.08051842
E31: Servicio de Actuador Neumáticos | F31: 0.073170732 | G31: =EDTN[[#This Row],[Nuevos Pesos]]*$G$30 -> 0.0058915917
E32: Servicio de Barrido y Llenado del Hidrógeno (H2) del Generador | F32: 0.024390244 | G32: =EDTN[[#This Row],[Nuevos Pesos]]*$G$30 -> 0.0019638639
E33: Servicio de Revisión de Manómetros y Termómetros | F33: 0.097560976 | G33: =EDTN[[#This Row],[Nuevos Pesos]]*$G$30 -> 0.0078554556
E34: Servicio de Revisión de Trasmisores de Presión | F34: 0.073170732 | G34: =EDTN[[#This Row],[Nuevos Pesos]]*$G$30 -> 0.0058915917
E35: Servicio de Mantenimiento de Válvulas de Control | F35: 0.073170732 | G35: =EDTN[[#This Row],[Nuevos Pesos]]*$G$30 -> 0.0058915917
E36: Servicio de Mantenimiento Interruptores de Temperatura | F36: 0.14634146 | G36: =EDTN[[#This Row],[Nuevos Pesos]]*$G$30 -> 0.011783183
E37: Servicio de Mantenimiento Interruptores de Nivel | F37: 0.14634146 | G37: =EDTN[[#This Row],[Nuevos Pesos]]*$G$30 -> 0.011783183
E38: Servicio de Mantenimiento Compuertas Aire Auxiliar y Combustión | F38: 0.073170732 | G38: =EDTN[[#This Row],[Nuevos Pesos]]*$G$30 -> 0.0058915917
E39: Servicio de Mantenimiento Interruptores de Flujo | F39: 0.14634146 | G39: =EDTN[[#This Row],[Nuevos Pesos]]*$G$30 -> 0.011783183
E40: Servicio de Revisión de Termocupla | F40: 0.14634146 | G40: =EDTN[[#This Row],[Nuevos Pesos]]*$G$30 -> 0.011783183
D41: 1.10 Mantenimiento compresores de aire | F41: 0.044703016 | G41: =EDTN[[#This Row],[Nuevos Pesos]]*$G$6 -> 0.034547631
E42: Mantenimiento de los compresores de aire | F42: 1 | G42: =EDTN[[#This Row],[Nuevos Pesos]]*G41 -> 0.034547631
D43: 0.0 Fin de actividades | F43: 0 | G43: =EDTN[[#This Row],[Nuevos Pesos]]*$G$6 -> 0
...

Sheet Plan OG
M2: =M5-K5 -> 0.0006681211 | N2: =N5-L5 -> 0.001257492 | O2: =O5-M5 -> 0.0020755527 | P2: =P5-N5 -> 0.0028132279 | Q2: =Q5-O5 -> 0.0026694199 | R2: =R5-P5 -> 0.014075633 | S2: =S5-Q5 -> 0.032596522 | T2: =T5-R5 -> 0.046257592 | ... DH2: =DH5-DF5 -> 0
L3: 45474 | M3: =+L3+7 -> 45481 | N3: =+M3+7 -> 45488 | O3: =+N3+7 -> 45495 | P3: =+O3+7 -> 45502 | Q3: =+P3+7 -> 45509 | R3: =+Q3+7 -> 45516 | S3: =+R3+7 -> 45523 | T3: =+S3+7 -> 45530 | ... EL3: =+EK3+7 -> 46384
B4: N1 | C4: N2 | D4: N3 | E4: N4 | F4: Dur. | G4: Comienzo | H4: Fin | I4: Dura. | J4: Pesos | K4: Column4 | L4: 01/07/2024 | M4: 08/07/2024 | N4: 15/07/2024 | O4: 22/07/2024 | P4: 29/07/2024 | Q4: 05/08/2024 | R4: 12/08/2024 | S4: 19/08/2024 | T4: 26/08/2024 | U4: 02/09/2024 | V4: 09/09/2024 | W4: 16/09/2024 | X4: 23/09/2024 | Y4: 30/09/2024 | Z4: 07/10/2024 | AA4: 14/10/2024 | AB4: 21/10/2024 | AC4: 28/10/2024 | AD4: 04/11/2024 | AE4: 11/11/2024 | AF4: 18/11/2024 | AG4: 25/11/2024 | AH4: 02/12/2024 | AI4: 09/12/2024 | AJ4: 16/12/2024 | AK4: 23/12/2024 | AL4: 30/12/2024 | AM4: 06/01/2025 | AN4: 13/01/2025 | AO4: 20/01/2025 | AP4: 27/01/2025 | AQ4: 03/02/2025 | AR4: 10/02/2025 | AS4: 17/02/2025 | AT4: 24/02/2025 | AU4: 03/03/2025 | AV4: 10/03/2025 | AW4: 17/03/2025 | AX4: 24/03/2025 | AY4: 31/03/2025 | AZ4: 07/04/2025 | BA4: 14/04/2025 | BB4: 21/04/2025 | BC4: 28/04/2025 | BD4: 05/05/2025 | BE4: 12/05/2025 | BF4: 19/05/2025 | BG4: 26/05/2025 | BH4: 02/06/2025 | BI4: 09/06/2025 | BJ4: 16/06/2025 | BK4: 23/06/2025 | BL4: 30/06/2025 | BM4: 07/07/2025 | BN4: 14/07/2025 | BO4: 21/07/2025 | BP4: 28/07/2025 | BQ4: 04/08/2025 | BR4: 11/08/2025 | BS4: 18/08/2025 | BT4: 25/08/2025 | BU4: 01/09/2025 | BV4: 08/09/2025 | BW4: 15/09/2025 | BX4: 22/09/2025 | BY4: 29/09/2025 | BZ4: 06/10/2025 | CA4: 13/10/2025 | CB4: 20/10/2025 | CC4: 27/10/2025 | CD4: 03/11/2025 | CE4: 10/11/2025 | CF4: 17/11/2025 | CG4: 24/11/2025 | CH4: 01/12/2025 | CI4: 08/12/2025 | CJ4: 15/12/2025 | CK4: 22/12/2025 | CL4: 29/12/2025 | CM4: 05/01/2026 | CN4: 12/01/2026 | CO4: 19/01/2026 | CP4: 26/01/2026 | CQ4: 02/02/2026 | CR4: 09/02/2026 | CS4: 16/02/2026 | CT4: 23/02/2026 | CU4: 02/03/2026 | CV4: 09/03/2026 | CW4: 16/03/2026 | CX4: 23/03/2026 | CY4: 30/03/2026 | CZ4: 06/04/2026 | DA4: 13/04/2026 | DB4: 20/04/2026 | DC4: 27/04/2026 | DD4: 04/05/2026 | DE4: 11/05/2026 | DF4: 18/05/2026 | DG4: 25/05/2026 | DH4: 01/06/2026 | DI4: 08/06/2026 | DJ4: 15/06/2026 | DK4: 22/06/2026 | DL4: 29/06/2026 | DM4: 06/07/2026 | DN4: 13/07/2026 | DO4: 20/07/2026 | DP4: 27/07/2026 | DQ4: 03/08/2026 | DR4: 10/08/2026 | DS4: 17/08/2026 | DT4: 24/08/2026 | DU4: 31/08/2026 | DV4: 07/09/2026 | DW4: 14/09/2026 | DX4: 21/09/2026 | DY4: 28/09/2026 | DZ4: 05/10/2026 | EA4: 12/10/2026 | EB4: 19/10/2026 | EC4: 26/10/2026 | ED4: 02/11/2026 | EE4: 09/11/2026 | EF4: 16/11/2026 | EG4: 23/11/2026 | EH4: 30/11/2026 | EI4: 07/12/2026 | EJ4: 14/12/2026 | EK4: 21/12/2026 | EL4: 28/12/2026
B5: Proyecto: Plan Master Tacoa | F5: 231 | G5: 45474 | H5: 45835 | I5: =+I6+I13+I78 -> 2650 | J5: 1 | L5: =+L6*$J$6+L13*$J$13+L78*$J$78 -> 8.7813633e-05 | M5: =+M6*$J$6+M13*$J$13+M78*$J$78 -> 0.0006681211 | N5: =+N6*$J$6+N13*$J$13+N78*$J$78 -> 0.0013453056 | O5: =+O6*$J$6+O13*$J$13+O78*$J$78 -> 0.0027436738 | P5: =+P6*$J$6+P13*$J$13+P78*$J$78 -> 0.0041585335 | Q5: =+Q6*$J$6+Q13*$J$13+Q78*$J$78 -> 0.0054130936 | R5: =+R6*$J$6+R13*$J$13+R78*$J$78 -> 0.018234166 | S5: =+S6*$J$6+S13*$J$13+S78*$J$78 -> 0.038009615 | ... EL5: =+EL6*$J$6+EL13*$J$13+EL78*$J$78 -> 1
C6: Actividades Preliminares | F6: 231 | G6: 45474 | H6: 45835 | I6: =+I7 -> 87 | J6: 1e-145 | L6: =+L7*$J$7 -> 0 | M6: =+M7*$J$7 -> 0.13103448 | N6: =+N7*$J$7 -> 0.30804598 | O6: =+O7*$J$7 -> 0.46206897 | P6: =+P7*$J$7 -> 0.66206897 | Q6: =+Q7*$J$7 -> 0.78735632 | R6: =+R7*$J$7 -> 1 | S6: =+S7*$J$7 -> 1 | ... EL6: =+EL7*$J$7 -> 1
D7: 0.0 Actividades preliminares | F7: 231 | G7: 45474 | H7: 45835 | I7: =+SUM(I8:I12) -> 87 | J7: 1 | L7: =+SUMPRODUCT($J$8:$J$12,L8:L12) -> 0 | M7: =+SUMPRODUCT($J$8:$J$12,M8:M12) -> 0.13103448 | N7: =+SUMPRODUCT($J$8:$J$12,N8:N12) -> 0.30804598 | O7: =+SUMPRODUCT($J$8:$J$12,O8:O12) -> 0.46206897 | P7: =+SUMPRODUCT($J$8:$J$12,P8:P12) -> 0.66206897 | Q7: =+SUMPRODUCT($J$8:$J$12,Q8:Q12) -> 0.78735632 | R7: =+SUMPRODUCT($J$8:$J$12,R8:R12) -> 1 | S7: =+SUMPRODUCT($J$8:$J$12,S8:S12) -> 1 | ... EL7: =+SUMPRODUCT($J$8:$J$12,EL8:EL12) -> 1
E8: Inicio de actividades | F8: 0 | G8: 45474 | H8: 45474 | I8: =+F8 -> 0 | J8: 1e-119 | L8: 0 | M8: 1 | N8: 1 | O8: 1 | P8: 1 | Q8: 1 | R8: 1 | S8: 1 | T8: 1 | U8: 1 | V8: 1 | W8: 1 | X8: 1 | Y8: 1 | Z8: 1 | AA8: 1 | AB8: 1 | AC8: 1 | AD8: 1 | AE8: 1 | AF8: 1 | AG8: 1 | AH8: 1 | AI8: 1 | AJ8: 1 | AK8: 1 | AL8: 1 | AM8: 1 | AN8: 1 | AO8: 1 | AP8: 1 | AQ8: 1 | AR8: 1 | AS8: 1 | AT8: 1 | AU8: 1 | AV8: 1 | AW8: 1 | AX8: 1 | AY8: 1 | AZ8: 1 | BA8: 1 | BB8: 1 | BC8: 1 | BD8: 1 | BE8: 1 | BF8: 1 | BG8: 1 | BH8: 1 | BI8: 1 | BJ8: 1 | BK8: 1 | BL8: 1 | BM8: 1 | BN8: 1 | BO8: 1 | BP8: 1 | BQ8: 1 | BR8: 1 | BS8: 1 | BT8: 1 | BU8: 1 | BV8: 1 | BW8: 1 | BX8: 1 | BY8: 1 | BZ8: 1 | CA8: 1 | CB8: 1 | CC8: 1 | CD8: 1 | CE8: 1 | CF8: 1 | CG8: 1 | CH8: 1 | CI8: 1 | CJ8: 1 | CK8: 1 | CL8: 1 | CM8: 1 | CN8: 1 | CO8: 1 | CP8: 1 | CQ8: 1 | CR8: 1 | CS8: 1 | CT8: 1 | CU8: 1 | CV8: 1 | CW8: 1 | CX8: 1 | CY8: 1 | CZ8: 1 | DA8: 1 | DB8: 1 | DC8: 1 | DD8: 1 | DE8: 1 | DF8: 1 | DG8: 1 | DH8: 1 | DI8: 1 | DJ8: 1 | DK8: 1 | DL8: 1 | DM8: 1 | DN8: 1 | DO8: 1 | DP8: 1 | DQ8: 1 | DR8: 1 | DS8: 1 | DT8: 1 | DU8: 1 | DV8: 1 | DW8: 1 | DX8: 1 | DY8: 1 | DZ8: 1 | EA8: 1 | EB8: 1 | EC8: 1 | ED8: 1 | EE8: 1 | EF8: 1 | EG8: 1 | EH8: 1 | EI8: 1 | EJ8: 1 | EK8: 1 | EL8: 1
E9: Fin de actividades | F9: 0 | G9: 45835 | H9: 45835 | I9: =+F9 -> 0 | J9: 1e-119 | L9: 0 | M9: 0 | N9: 0 | O9: 0 | P9: 0 | Q9: 0 | R9: 0 | S9: 0 | T9: 0 | U9: 0 | V9: 0 | W9: 0 | X9: 0 | Y9: 0 | Z9: 0 | AA9: 0 | AB9: 0 | AC9: 0 | AD9: 0 | AE9: 0 | AF9: 0 | AG9: 0 | AH9: 0 | AI9: 0 | AJ9: 0 | AK9: 0 | AL9: 0 | AM9: 0 | AN9: 0 | AO9: 0 | AP9: 0 | AQ9: 0 | AR9: 0 | AS9: 0 | AT9: 0 | AU9: 0 | AV9: 0 | AW9: 0 | AX9: 0 | AY9: 0 | AZ9: 0 | BA9: 0 | BB9: 0 | BC9: 0 | BD9: 0 | BE9: 0 | BF9: 0 | BG9: 0 | BH9: 0 | BI9: 0 | BJ9: 0 | BK9: 0 | BL9: 0 | BM9: 0 | BN9: 0 | BO9: 0 | BP9: 0 | BQ9: 0 | BR9: 0 | BS9: 0 | BT9: 0 | BU9: 0 | BV9: 0 | BW9: 0 | BX9: 0 | BY9: 0 | BZ9: 0 | CA9: 0 | CB9: 0 | CC9: 0 | CD9: 0 | CE9: 0 | CF9: 0 | CG9: 0 | CH9: 0 | CI9: 0 | CJ9: 0 | CK9: 0 | CL9: 0 | CM9: 0 | CN9: 0 | CO9: 0 | CP9: 0 | CQ9: 0 | CR9: 0 | CS9: 0 | CT9: 0 | CU9: 0 | CV9: 0 | CW9: 0 | CX9: 0 | CY9: 0 | CZ9: 0 | DA9: 0 | DB9: 0 | DC9: 0 | DD9: 0 | DE9: 0 | DF9: 0 | DG9: 0 | DH9: 0 | DI9: 0 | DJ9: 0 | DK9: 0 | DL9: 0 | DM9: 0 | DN9: 0 | DO9: 0 | DP9: 0 | DQ9: 0 | DR9: 0 | DS9: 0 | DT9: 0 | DU9: 0 | DV9: 0 | DW9: 0 | DX9: 0 | DY9: 0 | DZ9: 0 | EA9: 0 | EB9: 0 | EC9: 0 | ED9: 0 | EE9: 0 | EF9: 0 | EG9: 0 | EH9: 0 | EI9: 0 | EJ9: 0 | EK9: 0 | EL9: 0
E10: Movilizacion | F10: 25 | G10: 45474 | H10: 45510 | I10: =+F10 -> 25 | J10: 0.28735632 | L10: 0 | M10: 0.2 | N10: 0.4 | O10: 0.6 | P10: 0.8 | Q10: 0.9 | R10: 1 | S10: 1 | T10: 1 | U10: 1 | V10: 1 | W10: 1 | X10: 1 | Y10: 1 | Z10: 1 | AA10: 1 | AB10: 1 | AC10: 1 | AD10: 1 | AE10: 1 | AF10: 1 | AG10: 1 | AH10: 1 | AI10: 1 | AJ10: 1 | AK10: 1 | AL10: 1 | AM10: 1 | AN10: 1 | AO10: 1 | AP10: 1 | AQ10: 1 | AR10: 1 | AS10: 1 | AT10: 1 | AU10: 1 | AV10: 1 | AW10: 1 | AX10: 1 | AY10: 1 | AZ10: 1 | BA10: 1 | BB10: 1 | BC10: 1 | BD10: 1 | BE10: 1 | BF10: 1 | BG10: 1 | BH10: 1 | BI10: 1 | BJ10: 1 | BK10: 1 | BL10: 1 | BM10: 1 | BN10: 1 | BO10: 1 | BP10: 1 | BQ10: 1 | BR10: 1 | BS10: 1 | BT10: 1 | BU10: 1 | BV10: 1 | BW10: 1 | BX10: 1 | BY10: 1 | BZ10: 1 | CA10: 1 | CB10: 1 | CC10: 1 | CD10: 1 | CE10: 1 | CF10: 1 | CG10: 1 | CH10: 1 | CI10: 1 | CJ10: 1 | CK10: 1 | CL10: 1 | CM10: 1 | CN10: 1 | CO10: 1 | CP10: 1 | CQ10: 1 | CR10: 1 | CS10: 1 | CT10: 1 | CU10: 1 | CV10: 1 | CW10: 1 | CX10: 1 | CY10: 1 | CZ10: 1 | DA10: 1 | DB10: 1 | DC10: 1 | DD10: 1 | DE10: 1 | DF10: 1 | DG10: 1 | DH10: 1 | DI10: 1 | DJ10: 1 | DK10: 1 | DL10: 1 | DM10: 1 | DN10: 1 | DO10: 1 | DP10: 1 | DQ10: 1 | DR10: 1 | DS10: 1 | DT10: 1 | DU10: 1 | DV10: 1 | DW10: 1 | DX10: 1 | DY10: 1 | DZ10: 1 | EA10: 1 | EB10: 1 | EC10: 1 | ED10: 1 | EE10: 1 | EF10: 1 | EG10: 1 | EH10: 1 | EI10: 1 | EJ10: 1 | EK10: 1 | EL10: 1
E11: Preparacion del campamento | F11: 22 | G11: 45474 | H11: 45505 | I11: =+F11 -> 22 | J11: 0.25287356 | L11: 0 | M11: 0.2 | N11: 0.4 | O11: 0.6 | P11: 0.8 | Q11: 1 | R11: 1 | S11: 1 | T11: 1 | U11: 1 | V11: 1 | W11: 1 | X11: 1 | Y11: 1 | Z11: 1 | AA11: 1 | AB11: 1 | AC11: 1 | AD11: 1 | AE11: 1 | AF11: 1 | AG11: 1 | AH11: 1 | AI11: 1 | AJ11: 1 | AK11: 1 | AL11: 1 | AM11: 1 | AN11: 1 | AO11: 1 | AP11: 1 | AQ11: 1 | AR11: 1 | AS11: 1 | AT11: 1 | AU11: 1 | AV11: 1 | AW11: 1 | AX11: 1 | AY11: 1 | AZ11: 1 | BA11: 1 | BB11: 1 | BC11: 1 | BD11: 1 | BE11: 1 | BF11: 1 | BG11: 1 | BH11: 1 | BI11: 1 | BJ11: 1 | BK11: 1 | BL11: 1 | BM11: 1 | BN11: 1 | BO11: 1 | BP11: 1 | BQ11: 1 | BR11: 1 | BS11: 1 | BT11: 1 | BU11: 1 | BV11: 1 | BW11: 1 | BX11: 1 | BY11: 1 | BZ11: 1 | CA11: 1 | CB11: 1 | CC11: 1 | CD11: 1 | CE11: 1 | CF11: 1 | CG11: 1 | CH11: 1 | CI11: 1 | CJ11: 1 | CK11: 1 | CL11: 1 | CM11: 1 | CN11: 1 | CO11: 1 | CP11: 1 | CQ11: 1 | CR11: 1 | CS11: 1 | CT11: 1 | CU11: 1 | CV11: 1 | CW11: 1 | CX11: 1 | CY11: 1 | CZ11: 1 | DA11: 1 | DB11: 1 | DC11: 1 | DD11: 1 | DE11: 1 | DF11: 1 | DG11: 1 | DH11: 1 | DI11: 1 | DJ11: 1 | DK11: 1 | DL11: 1 | DM11: 1 | DN11: 1 | DO11: 1 | DP11: 1 | DQ11: 1 | DR11: 1 | DS11: 1 | DT11: 1 | DU11: 1 | DV11: 1 | DW11: 1 | DX11: 1 | DY11: 1 | DZ11: 1 | EA11: 1 | EB11: 1 | EC11: 1 | ED11: 1 | EE11: 1 | EF11: 1 | EG11: 1 | EH11: 1 | EI11: 1 | EJ11: 1 | EK11: 1 | EL11: 1
E12: Limpieza de áreas y adecuación de plataformas de acceso | F12: 40 | G12: 45482 | H12: 45538 | I12: =+F12 -> 40 | J12: 0.45977011 | L12: 0 | M12: 0.05 | N12: 0.2 | O12: 0.3 | P12: 0.5 | Q12: 0.6 | R12: 1 | S12: 1 | T12: 1 | U12: 1 | V12: 1 | W12: 1 | X12: 1 | Y12: 1 | Z12: 1 | AA12: 1 | AB12: 1 | AC12: 1 | AD12: 1 | AE12: 1 | AF12: 1 | AG12: 1 | AH12: 1 | AI12: 1 | AJ12: 1 | AK12: 1 | AL12: 1 | AM12: 1 | AN12: 1 | AO12: 1 | AP12: 1 | AQ12: 1 | AR12: 1 | AS12: 1 | AT12: 1 | AU12: 1 | AV12: 1 | AW12: 1 | AX12: 1 | AY12: 1 | AZ12: 1 | BA12: 1 | BB12: 1 | BC12: 1 | BD12: 1 | BE12: 1 | BF12: 1 | BG12: 1 | BH12: 1 | BI12: 1 | BJ12: 1 | BK12: 1 | BL12: 1 | BM12: 1 | BN12: 1 | BO12: 1 | BP12: 1 | BQ12: 1 | BR12: 1 | BS12: 1 | BT12: 1 | BU12: 1 | BV12: 1 | BW12: 1 | BX12: 1 | BY12: 1 | BZ12: 1 | CA12: 1 | CB12: 1 | CC12: 1 | CD12: 1 | CE12: 1 | CF12: 1 | CG12: 1 | CH12: 1 | CI12: 1 | CJ12: 1 | CK12: 1 | CL12: 1 | CM12: 1 | CN12: 1 | CO12: 1 | CP12: 1 | CQ12: 1 | CR12: 1 | CS12: 1 | CT12: 1 | CU12: 1 | CV12: 1 | CW12: 1 | CX12: 1 | CY12: 1 | CZ12: 1 | DA12: 1 | DB12: 1 | DC12: 1 | DD12: 1 | DE12: 1 | DF12: 1 | DG12: 1 | DH12: 1 | DI12: 1 | DJ12: 1 | DK12: 1 | DL12: 1 | DM12: 1 | DN12: 1 | DO12: 1 | DP12: 1 | DQ12: 1 | DR12: 1 | DS12: 1 | DT12: 1 | DU12: 1 | DV12: 1 | DW12: 1 | DX12: 1 | DY12: 1 | DZ12: 1 | EA12: 1 | EB12: 1 | EC12: 1 | ED12: 1 | EE12: 1 | EF12: 1 | EG12: 1 | EH12: 1 | EI12: 1 | EJ12: 1 | EK12: 1 | EL12: 1
C13: Mantenimiento del Generador de Vapor (Caldera) y Equipos Auxiliares | F13: 217 | G13: 45489 | H13: 45828 | I13: =+I14+I17+I24+I26+I34+I38+I41+I43+I48+I58+I72+I74 -> 1775 | J13: 0.77282549 | L13: =+L14*$J$14+L17*$J$17+L24*$J$24+L26*$J$26+L34*$J$34+L38*$J$38+L41*$J$41+L43*$J$43+L48*$J$48+L58*$J$58+L72*$J$72+L74*$J$74 -> 0 | M13: =+M14*$J$14+M17*$J$17+M24*$J$24+M26*$J$26+M34*$J$34+M38*$J$38+M41*$J$41+M43*$J$43+M48*$J$48+M58*$J$58+M72*$J$72+M74*$J$74 -> 0.00053986962 | N13: =+N14*$J$14+N17*$J$17+N24*$J$24+N26*$J$26+N34*$J$34+N38*$J$38+N41*$J$41+N43*$J$43+N48*$J$48+N58*$J$58+N72*$J$72+N74*$J$74 -> 0.0010914669 | O13: =+O14*$J$14+O17*$J$17+O24*$J$24+O26*$J$26+O34*$J$34+O38*$J$38+O41*$J$41+O43*$J$43+O48*$J$48+O58*$J$58+O72*$J$72+O74*$J$74 -> 0.002576242 | P13: =+P14*$J$14+P17*$J$17+P24*$J$24+P26*$J$26+P34*$J$34+P38*$J$38+P41*$J$41+P43*$J$43+P48*$J$48+P58*$J$58+P72*$J$72+P74*$J$74 -> 0.0040823564 | Q13: =+Q14*$J$14+Q17*$J$17+Q24*$J$24+Q26*$J$26+Q34*$J$34+Q38*$J$38+Q41*$J$41+Q43*$J$43+Q48*$J$48+Q58*$J$58+Q72*$J$72+Q74*$J$74 -> 0.0053810507 | R13: =+R14*$J$14+R17*$J$17+R24*$J$24+R26*$J$26+R34*$J$34+R38*$J$38+R41*$J$41+R43*$J$43+R48*$J$48+R58*$J$58+R72*$J$72+R74*$J$74 -> 0.021646271 | S13: =+S14*$J$14+S17*$J$17+S24*$J$24+S26*$J$26+S34*$J$34+S38*$J$38+S41*$J$41+S43*$J$43+S48*$J$48+S58*$J$58+S72*$J$72+S74*$J$74 -> 0.046910128 | ... EL13: =+EL14*$J$14+EL17*$J$17+EL24*$J$24+EL26*$J$26+EL34*$J$34+EL38*$J$38+EL41*$J$41+EL43*$J$43+EL48*$J$48+EL58*$J$58+EL72*$J$72+EL74*$J$74 -> 1
D14: 0.0 Actividades preliminares | F14: 55 | G14: 45489 | H14: 45566 | I14: =+SUM(I15:I16) -> 75 | J14: 0.02 | L14: =+SUMPRODUCT($J$15:$J$16,L15:L16) -> 0 | M14: =+SUMPRODUCT($J$15:$J$16,M15:M16) -> 0.026666667 | N14: =+SUMPRODUCT($J$15:$J$16,N15:N16) -> 0.053333333 | O14: =+SUMPRODUCT($J$15:$J$16,O15:O16) -> 0.10666667 | P14: =+SUMPRODUCT($J$15:$J$16,P15:P16) -> 0.16 | Q14: =+SUMPRODUCT($J$15:$J$16,Q15:Q16) -> 0.21333333 | R14: =+SUMPRODUCT($J$15:$J$16,R15:R16) -> 0.24 | S14: =+SUMPRODUCT($J$15:$J$16,S15:S16) -> 0.26666667 | ... EL14: =+SUMPRODUCT($J$15:$J$16,EL15:EL16) -> 1
E15: Inspecciones visuales externas e internas | F15: 20 | G15: 45489 | H15: 45517 | I15: =+F15 -> 20 | J15: 0.26666667 | L15: 0 | M15: 0.1 | N15: 0.2 | O15: 0.4 | P15: 0.6 | Q15: 0.8 | R15: 0.9 | S15: 1 | T15: 1 | U15: 1 | V15: 1 | W15: 1 | X15: 1 | Y15: 1 | Z15: 1 | AA15: 1 | AB15: 1 | AC15: 1 | AD15: 1 | AE15: 1 | AF15: 1 | AG15: 1 | AH15: 1 | AI15: 1 | AJ15: 1 | AK15: 1 | AL15: 1 | AM15: 1 | AN15: 1 | AO15: 1 | AP15: 1 | AQ15: 1 | AR15: 1 | AS15: 1 | AT15: 1 | AU15: 1 | AV15: 1 | AW15: 1 | AX15: 1 | AY15: 1 | AZ15: 1 | BA15: 1 | BB15: 1 | BC15: 1 | BD15: 1 | BE15: 1 | BF15: 1 | BG15: 1 | BH15: 1 | BI15: 1 | BJ15: 1 | BK15: 1 | BL15: 1 | BM15: 1 | BN15: 1 | BO15: 1 | BP15: 1 | BQ15: 1 | BR15: 1 | BS15: 1 | BT15: 1 | BU15: 1 | BV15: 1 | BW15: 1 | BX15: 1 | BY15: 1 | BZ15: 1 | CA15: 1 | CB15: 1 | CC15: 1 | CD15: 1 | CE15: 1 | CF15: 1 | CG15: 1 | CH15: 1 | CI15: 1 | CJ15: 1 | CK15: 1 | CL15: 1 | CM15: 1 | CN15: 1 | CO15: 1 | CP15: 1 | CQ15: 1 | CR15: 1 | CS15: 1 | CT15: 1 | CU15: 1 | CV15: 1 | CW15: 1 | CX15: 1 | CY15: 1 | CZ15: 1 | DA15: 1 | DB15: 1 | DC15: 1 | DD15: 1 | DE15: 1 | DF15: 1 | DG15: 1 | DH15: 1 | DI15: 1 | DJ15: 1 | DK15: 1 | DL15: 1 | DM15: 1 | DN15: 1 | DO15: 1 | DP15: 1 | DQ15: 1 | DR15: 1 | DS15: 1 | DT15: 1 | DU15: 1 | DV15: 1 | DW15: 1 | DX15: 1 | DY15: 1 | DZ15: 1 | EA15: 1 | EB15: 1 | EC15: 1 | ED15: 1 | EE15: 1 | EF15: 1 | EG15: 1 | EH15: 1 | EI15: 1 | EJ15: 1 | EK15: 1 | EL15: 1
E16: Reparación de caminerias, grating, escaleras corroidas | F16: 55 | G16: 45489 | H16: 45566 | I16: =+F16 -> 55 | J16: 0.73333333 | L16: 0 | M16: 0 | N16: 0 | O16: 0 | P16: 0 | Q16: 0 | R16: 0 | S16: 0 | T16: 0 | U16: 0.15 | V16: 0.16201144 | W16: 0.22582171 | X16: 0.22582171 | Y16: 0.37054781 | Z16: 0.60465183 | AA16: 0.68078117 | AB16: 0.75829186 | AC16: 1 | AD16: 1 | AE16: 1 | AF16: 1 | AG16: 1 | AH16: 1 | AI16: 1 | AJ16: 1 | AK16: 1 | AL16: 1 | AM16: 1 | AN16: 1 | AO16: 1 | AP16: 1 | AQ16: 1 | AR16: 1 | AS16: 1 | AT16: 1 | AU16: 1 | AV16: 1 | AW16: 1 | AX16: 1 | AY16: 1 | AZ16: 1 | BA16: 1 | BB16: 1 | BC16: 1 | BD16: 1 | BE16: 1 | BF16: 1 | BG16: 1 | BH16: 1 | BI16: 1 | BJ16: 1 | BK16: 1 | BL16: 1 | BM16: 1 | BN16: 1 | BO16: 1 | BP16: 1 | BQ16: 1 | BR16: 1 | BS16: 1 | BT16: 1 | BU16: 1 | BV16: 1 | BW16: 1 | BX16: 1 | BY16: 1 | BZ16: 1 | CA16: 1 | CB16: 1 | CC16: 1 | CD16: 1 | CE16: 1 | CF16: 1 | CG16: 1 | CH16: 1 | CI16: 1 | CJ16: 1 | CK16: 1 | CL16: 1 | CM16: 1 | CN16: 1 | CO16: 1 | CP16: 1 | CQ16: 1 | CR16: 1 | CS16: 1 | CT16: 1 | CU16: 1 | CV16: 1 | CW16: 1 | CX16: 1 | CY16: 1 | CZ16: 1 | DA16: 1 | DB16: 1 | DC16: 1 | DD16: 1 | DE16: 1 | DF16: 1 | DG16: 1 | DH16: 1 | DI16: 1 | DJ16: 1 | DK16: 1 | DL16: 1 | DM16: 1 | DN16: 1 | DO16: 1 | DP16: 1 | DQ16: 1 | DR16: 1 | DS16: 1 | DT16: 1 | DU16: 1 | DV16: 1 | DW16: 1 | DX16: 1 | DY16: 1 | DZ16: 1 | EA16: 1 | EB16: 1 | EC16: 1 | ED16: 1 | EE16: 1 | EF16: 1 | EG16: 1 | EH16: 1 | EI16: 1 | EJ16: 1 | EK16: 1 | EL16: 1
D17: 1.1 Reparación de expansiones metálicas | F17: 105 | G17: 45489 | H17: 45636 | I17: =+SUM(I18:I23) -> 195 | J17: 0.20327658 | L17: =+SUMPRODUCT($J$18:$J$23,L18:L23) -> 0 | M17: =+SUMPRODUCT($J$18:$J$23,M18:M23) -> 0 | N17: =+SUMPRODUCT($J$18:$J$23,N18:N23) -> 0 | O17: =+SUMPRODUCT($J$18:$J$23,O18:O23) -> 0 | P17: =+SUMPRODUCT($J$18:$J$23,P18:P23) -> 0 | Q17: =+SUMPRODUCT($J$18:$J$23,Q18:Q23) -> 0 | R17: =+SUMPRODUCT($J$18:$J$23,R18:R23) -> 0.044497232 | S17: =+SUMPRODUCT($J$18:$J$23,S18:S23) -> 0.11434791 | ... EL17: =+SUMPRODUCT($J$18:$J$23,EL18:EL23) -> 1
E18: Procura de laminas de acero al carbono | F18: 10 | G18: 45518 | H18: 45531 | I18: =+F18 -> 10 | J18: 0.05 | L18: 0 | M18: 0 | N18: 0 | O18: 0 | P18: 0 | Q18: 0 | R18: 0 | S18: 0.5 | T18: 0.5 | U18: 0.5 | V18: 0.5 | W18: 0.5 | X18: 0.5 | Y18: 0.5 | Z18: 0.5 | AA18: 0.5 | AB18: 0.5 | AC18: 0.6 | AD18: 0.6 | AE18: 0.6 | AF18: 0.6 | AG18: 1 | AH18: 1 | AI18: 1 | AJ18: 1 | AK18: 1 | AL18: 1 | AM18: 1 | AN18: 1 | AO18: 1 | AP18: 1 | AQ18: 1 | AR18: 1 | AS18: 1 | AT18: 1 | AU18: 1 | AV18: 1 | AW18: 1 | AX18: 1 | AY18: 1 | AZ18: 1 | BA18: 1 | BB18: 1 | BC18: 1 | BD18: 1 | BE18: 1 | BF18: 1 | BG18: 1 | BH18: 1 | BI18: 1 | BJ18: 1 | BK18: 1 | BL18: 1 | BM18: 1 | BN18: 1 | BO18: 1 | BP18: 1 | BQ18: 1 | BR18: 1 | BS18: 1 | BT18: 1 | BU18: 1 | BV18: 1 | BW18: 1 | BX18: 1 | BY18: 1 | BZ18: 1 | CA18: 1 | CB18: 1 | CC18: 1 | CD18: 1 | CE18: 1 | CF18: 1 | CG18: 1 | CH18: 1 | CI18: 1 | CJ18: 1 | CK18: 1 | CL18: 1 | CM18: 1 | CN18: 1 | CO18: 1 | CP18: 1 | CQ18: 1 | CR18: 1 | CS18: 1 | CT18: 1 | CU18: 1 | CV18: 1 | CW18: 1 | CX18: 1 | CY18: 1 | CZ18: 1 | DA18: 1 | DB18: 1 | DC18: 1 | DD18: 1 | DE18: 1 | DF18: 1 | DG18: 1 | DH18: 1 | DI18: 1 | DJ18: 1 | DK18: 1 | DL18: 1 | DM18: 1 | DN18: 1 | DO18: 1 | DP18: 1 | DQ18: 1 | DR18: 1 | DS18: 1 | DT18: 1 | DU18: 1 | DV18: 1 | DW18: 1 | DX18: 1 | DY18: 1 | DZ18: 1 | EA18: 1 | EB18: 1 | EC18: 1 | ED18: 1 | EE18: 1 | EF18: 1 | EG18: 1 | EH18: 1 | EI18: 1 | EJ18: 1 | EK18: 1 | EL18: 1
E19: Fabricación en taller de expansiones | F19: 40 | G19: 45532 | H19: 45587 | I19: =+F19 -> 40 | J19: 0.08 | L19: 0 | M19: 0 | N19: 0 | O19: 0 | P19: 0 | Q19: 0 | R19: 0 | S19: 0.0044180727 | T19: 0.28170638 | U19: 0.44661817 | V19: 0.44682734 | W19: 0.4471411 | X19: 0.44741303 | Y19: 0.4474967 | Z19: 0.44751762 | AA19: 0.44751762 | AB19: 0.44751762 | AC19: 0.44751762 | AD19: 0.44751762 | AE19: 0.44751762 | AF19: 0.44751762 | AG19: 0.44751762 | AH19: 0.50268846 | AI19: 0.74377463 | AJ19: 0.85568156 | AK19: 1 | AL19: 1 | AM19: 1 | AN19: 1 | AO19: 1 | AP19: 1 | AQ19: 1 | AR19: 1 | AS19: 1 | AT19: 1 | AU19: 1 | AV19: 1 | AW19: 1 | AX19: 1 | AY19: 1 | AZ19: 1 | BA19: 1 | BB19: 1 | BC19: 1 | BD19: 1 | BE19: 1 | BF19: 1 | BG19: 1 | BH19: 1 | BI19: 1 | BJ19: 1 | BK19: 1 | BL19: 1 | BM19: 1 | BN19: 1 | BO19: 1 | BP19: 1 | BQ19: 1 | BR19: 1 | BS19: 1 | BT19: 1 | BU19: 1 | BV19: 1 | BW19: 1 | BX19: 1 | BY19: 1 | BZ19: 1 | CA19: 1 | CB19: 1 | CC19: 1 | CD19: 1 | CE19: 1 | CF19: 1 | CG19: 1 | CH19: 1 | CI19: 1 | CJ19: 1 | CK19: 1 | CL19: 1 | CM19: 1 | CN19: 1 | CO19: 1 | CP19: 1 | CQ19: 1 | CR19: 1 | CS19: 1 | CT19: 1 | CU19: 1 | CV19: 1 | CW19: 1 | CX19: 1 | CY19: 1 | CZ19: 1 | DA19: 1 | DB19: 1 | DC19: 1 | DD19: 1 | DE19: 1 | DF19: 1 | DG19: 1 | DH19: 1 | DI19: 1 | DJ19: 1 | DK19: 1 | DL19: 1 | DM19: 1 | DN19: 1 | DO19: 1 | DP19: 1 | DQ19: 1 | DR19: 1 | DS19: 1 | DT19: 1 | DU19: 1 | DV19: 1 | DW19: 1 | DX19: 1 | DY19: 1 | DZ19: 1 | EA19: 1 | EB19: 1 | EC19: 1 | ED19: 1 | EE19: 1 | EF19: 1 | EG19: 1 | EH19: 1 | EI19: 1 | EJ19: 1 | EK19: 1 | EL19: 1
E20: Remoción de expansiones deterioradas | F20: 40 | G20: 45489 | H20: 45545 | I20: =+F20 -> 40 | J20: 0.2 | L20: 0 | M20: 0 | N20: 0 | O20: 0 | P20: 0 | Q20: 0 | R20: 0.22248616 | S20: 0.44497232 | T20: 0.60883219 | U20: 0.6679709 | V20: 0.72130751 | W20: 0.73350279 | X20: 0.75644306 | Y20: 0.85058691 | Z20: 0.86718836 | AA20: 0.92597071 | AB20: 0.92597071 | AC20: 0.92597071 | AD20: 0.92597071 | AE20: 0.92597071 | AF20: 0.92597071 | AG20: 0.92597071 | AH20: 0.92597071 | AI20: 0.92597071 | AJ20: 0.92597071 | AK20: 0.92597071 | AL20: 0.92597071 | AM20: 0.92597071 | AN20: 0.92597071 | AO20: 0.92597071 | AP20: 0.92597071 | AQ20: 0.92597071 | AR20: 0.92597071 | AS20: 0.92597071 | AT20: 0.92597071 | AU20: 0.92597071 | AV20: 0.92597071 | AW20: 0.92597071 | AX20: 0.92597071 | AY20: 0.92597071 | AZ20: 0.94077071 | BA20: 0.95557071 | BB20: 0.97037071 | BC20: 0.98517071 | BD20: 0.99997071 | BE20: 1 | BF20: 1 | BG20: 1 | BH20: 1 | BI20: 1 | BJ20: 1 | BK20: 1 | BL20: 1 | BM20: 1 | BN20: 1 | BO20: 1 | BP20: 1 | BQ20: 1 | BR20: 1 | BS20: 1 | BT20: 1 | BU20: 1 | BV20: 1 | BW20: 1 | BX20: 1 | BY20: 1 | BZ20: 1 | CA20: 1 | CB20: 1 | CC20: 1 | CD20: 1 | CE20: 1 | CF20: 1 | CG20: 1 | CH20: 1 | CI20: 1 | CJ20: 1 | CK20: 1 | CL20: 1 | CM20: 1 | CN20: 1 | CO20: 1 | CP20: 1 | CQ20: 1 | CR20: 1 | CS20: 1 | CT20: 1 | CU20: 1 | CV20: 1 | CW20: 1 | CX20: 1 | CY20: 1 | CZ20: 1 | DA20: 1 | DB20: 1 | DC20: 1 | DD20: 1 | DE20: 1 | DF20: 1 | DG20: 1 | DH20: 1 | DI20: 1 | DJ20: 1 | DK20: 1 | DL20: 1 | DM20: 1 | DN20: 1 | DO20: 1 | DP20: 1 | DQ20: 1 | DR20: 1 | DS20: 1 | DT20: 1 | DU20: 1 | DV20: 1 | DW20: 1 | DX20: 1 | DY20: 1 | DZ20: 1 | EA20: 1 | EB20: 1 | EC20: 1 | ED20: 1 | EE20: 1 | EF20: 1 | EG20: 1 | EH20: 1 | EI20: 1 | EJ20: 1 | EK20: 1 | EL20: 1
E21: Instalación de expansiones nuevas | F21: 35 | G21: 45560 | H21: 45608 | I21: =+F21 -> 35 | J21: 0.4 | L21: 0 | M21: 0 | N21: 0 | O21: 0 | P21: 0 | Q21: 0 | R21: 0 | S21: 0 | T21: 0 | U21: 0 | V21: 0 | W21: 0 | X21: 0 | Y21: 0 | Z21: 0 | AA21: 0 | AB21: 0.050939064 | AC21: 0.058769114 | AD21: 0.065177507 | AE21: 0.069442478 | AF21: 0.29461427 | AG21: 0.34845301 | AH21: 0.45892499 | AI21: 0.54152667 | AJ21: 0.66956246 | AK21: 0.69582989 | AL21: 0.69582989 | AM21: 0.69582989 | AN21: 0.69835766 | AO21: 0.69835766 | AP21: 0.71425766 | AQ21: 0.73015766 | AR21: 0.74605766 | AS21: 0.76195766 | AT21: 0.77785766 | AU21: 0.79375766 | AV21: 0.80965766 | AW21: 0.82555766 | AX21: 0.84145766 | AY21: 0.85735766 | AZ21: 0.87325766 | BA21: 0.88915766 | BB21: 0.90505766 | BC21: 0.92095766 | BD21: 0.93685766 | BE21: 0.95275766 | BF21: 0.96865766 | BG21: 0.98455766 | BH21: 1.0004577 | BI21: 1 | BJ21: 1 | BK21: 1 | BL21: 1 | BM21: 1 | BN21: 1 | BO21: 1 | BP21: 1 | BQ21: 1 | BR21: 1 | BS21: 1 | BT21: 1 | BU21: 1 | BV21: 1 | BW21: 1 | BX21: 1 | BY21: 1 | BZ21: 1 | CA21: 1 | CB21: 1 | CC21: 1 | CD21: 1 | CE21: 1 | CF21: 1 | CG21: 1 | CH21: 1 | CI21: 1 | CJ21: 1 | CK21: 1 | CL21: 1 | CM21: 1 | CN21: 1 | CO21: 1 | CP21: 1 | CQ21: 1 | CR21: 1 | CS21: 1 | CT21: 1 | CU21: 1 | CV21: 1 | CW21: 1 | CX21: 1 | CY21: 1 | CZ21: 1 | DA21: 1 | DB21: 1 | DC21: 1 | DD21: 1 | DE21: 1 | DF21: 1 | DG21: 1 | DH21: 1 | DI21: 1 | DJ21: 1 | DK21: 1 | DL21: 1 | DM21: 1 | DN21: 1 | DO21: 1 | DP21: 1 | DQ21: 1 | DR21: 1 | DS21: 1 | DT21: 1 | DU21: 1 | DV21: 1 | DW21: 1 | DX21: 1 | DY21: 1 | DZ21: 1 | EA21: 1 | EB21: 1 | EC21: 1 | ED21: 1 | EE21: 1 | EF21: 1 | EG21: 1 | EH21: 1 | EI21: 1 | EJ21: 1 | EK21: 1 | EL21: 1
E22: Galvanizado de expansiones fabricadas | F22: 35 | G22: 45574 | H22: 45622 | I22: =+F22 -> 35 | J22: 0.12 | L22: 0 | M22: 0 | N22: 0 | O22: 0 | P22: 0 | Q22: 0 | R22: 0 | S22: 0 | T22: 0 | U22: 0 | V22: 0 | W22: 0 | X22: 0.40195635 | Y22: 0.41363581 | Z22: 0.41363581 | AA22: 0.44661817 | AB22: 0.44661817 | AC22: 0.44661817 | AD22: 0.44661817 | AE22: 0.44661817 | AF22: 0.44661817 | AG22: 0.44661817 | AH22: 0.47094348 | AI22: 0.47094348 | AJ22: 0.67840038 | AK22: 0.67840038 | AL22: 0.67840038 | AM22: 0.67840038 | AN22: 0.67840038 | AO22: 0.67840038 | AP22: 0.69850038 | AQ22: 0.71860038 | AR22: 0.73870038 | AS22: 0.75880038 | AT22: 0.77890038 | AU22: 0.79900038 | AV22: 0.81910038 | AW22: 0.83920038 | AX22: 0.85930038 | AY22: 0.87940038 | AZ22: 0.89950038 | BA22: 0.91960038 | BB22: 0.93970038 | BC22: 0.95980038 | BD22: 0.97990038 | BE22: 1.0000004 | BF22: 1 | BG22: 1 | BH22: 1 | BI22: 1 | BJ22: 1 | BK22: 1 | BL22: 1 | BM22: 1 | BN22: 1 | BO22: 1 | BP22: 1 | BQ22: 1 | BR22: 1 | BS22: 1 | BT22: 1 | BU22: 1 | BV22: 1 | BW22: 1 | BX22: 1 | BY22: 1 | BZ22: 1 | CA22: 1 | CB22: 1 | CC22: 1 | CD22: 1 | CE22: 1 | CF22: 1 | CG22: 1 | CH22: 1 | CI22: 1 | CJ22: 1 | CK22: 1 | CL22: 1 | CM22: 1 | CN22: 1 | CO22: 1 | CP22: 1 | CQ22: 1 | CR22: 1 | CS22: 1 | CT22: 1 | CU22: 1 | CV22: 1 | CW22: 1 | CX22: 1 | CY22: 1 | CZ22: 1 | DA22: 1 | DB22: 1 | DC22: 1 | DD22: 1 | DE22: 1 | DF22: 1 | DG22: 1 | DH22: 1 | DI22: 1 | DJ22: 1 | DK22: 1 | DL22: 1 | DM22: 1 | DN22: 1 | DO22: 1 | DP22: 1 | DQ22: 1 | DR22: 1 | DS22: 1 | DT22: 1 | DU22: 1 | DV22: 1 | DW22: 1 | DX22: 1 | DY22: 1 | DZ22: 1 | EA22: 1 | EB22: 1 | EC22: 1 | ED22: 1 | EE22: 1 | EF22: 1 | EG22: 1 | EH22: 1 | EI22: 1 | EJ22: 1 | EK22: 1 | EL22: 1
E23: Instalación de aislamiento y enchaquetado aluminio | F23: 35 | G23: 45588 | H23: 45636 | I23: =+F23 -> 35 | J23: 0.15 | L23: 0 | M23: 0 | N23: 0 | O23: 0 | P23: 0 | Q23: 0 | R23: 0 | S23: 0 | T23: 0 | U23: 0 | V23: 0 | W23: 0 | X23: 0 | Y23: 0 | Z23: 0 | AA23: 0 | AB23: 0 | AC23: 0 | AD23: 0 | AE23: 0 | AF23: 0 | AG23: 0 | AH23: 0 | AI23: 0 | AJ23: 0 | AK23: 0 | AL23: 0 | AM23: 0 | AN23: 0 | AO23: 0 | AP23: 0 | AQ23: 0 | AR23: 0 | AS23: 0 | AT23: 0 | AU23: 0 | AV23: 0 | AW23: 0 | AX23: 0 | AY23: 0 | AZ23: 0 | BA23: 0.0833 | BB23: 0.1666 | BC23: 0.2499 | BD23: 0.3332 | BE23: 0.4165 | BF23: 0.4998 | BG23: 0.5831 | BH23: 0.6664 | BI23: 0.7497 | BJ23: 0.833 | BK23: 0.9163 | BL23: 0.9996 | BM23: 1 | BN23: 1 | BO23: 1 | BP23: 1 | BQ23: 1 | BR23: 1 | BS23: 1 | BT23: 1 | BU23: 1 | BV23: 1 | BW23: 1 | BX23: 1 | BY23: 1 | BZ23: 1 | CA23: 1 | CB23: 1 | CC23: 1 | CD23: 1 | CE23: 1 | CF23: 1 | CG23: 1 | CH23: 1 | CI23: 1 | CJ23: 1 | CK23: 1 | CL23: 1 | CM23: 1 | CN23: 1 | CO23: 1 | CP23: 1 | CQ23: 1 | CR23: 1 | CS23: 1 | CT23: 1 | CU23: 1 | CV23: 1 | CW23: 1 | CX23: 1 | CY23: 1 | CZ23: 1 | DA23: 1 | DB23: 1 | DC23: 1 | DD23: 1 | DE23: 1 | DF23: 1 | DG23: 1 | DH23: 1 | DI23: 1 | DJ23: 1 | DK23: 1 | DL23: 1 | DM23: 1 | DN23: 1 | DO23: 1 | DP23: 1 | DQ23: 1 | DR23: 1 | DS23: 1 | DT23: 1 | DU23: 1 | DV23: 1 | DW23: 1 | DX23: 1 | DY23: 1 | DZ23: 1 | EA23: 1 | EB23: 1 | EC23: 1 | ED23: 1 | EE23: 1 | EF23: 1 | EG23: 1 | EH23: 1 | EI23: 1 | EJ23: 1 | EK23: 1 | EL23: 1
D24: 1.2 Reemplazo de tubos de gas | F24: 60 | G24: 45539 | H24: 45622 | I24: =+I25 -> 60 | J24: 0.062393862 | L24: =+L25*$J$25 -> 0 | M24: =+M25*$J$25 -> 0 | N24: =+N25*$J$25 -> 0 | O24: =+O25*$J$25 -> 0 | P24: =+P25*$J$25 -> 0 | Q24: =+Q25*$J$25 -> 0 | R24: =+R25*$J$25 -> 0.02671875 | S24: =+S25*$J$25 -> 0.0734375 | ... EL24: =+EL25*$J$25 -> 1
E25: Reemplazo de tubos de gas de los quemdores de la caldera | F25: 60 | G25: 45539 | H25: 45622 | I25: =+F25 -> 60 | J25: 1 | L25: 0 | M25: 0 | N25: 0 | O25: 0 | P25: 0 | Q25: 0 | R25: 0.02671875 | S25: 0.0734375 | T25: 0.22 | U25: 0.2425 | V25: 0.35 | W25: 0.35 | X25: 0.35 | Y25: 0.35 | Z25: 0.35 | AA25: 0.3725 | AB25: 0.5 | AC25: 0.575 | AD25: 0.5778125 | AE25: 0.58625 | AF25: 0.588125 | AG25: 0.5898125 | AH25: 0.60082812 | AI25: 0.6048125 | AJ25: 0.60783594 | AK25: 0.60851563 | AL25: 0.60851563 | AM25: 0.60851563 | AN25: 0.61564062 | AO25: 0.62201562 | AP25: 0.626375 | AQ25: 0.6355 | AR25: 0.64654687 | AS25: 0.6566875 | AT25: 0.6757875 | AU25: 0.6948875 | AV25: 0.7139875 | AW25: 0.7330875 | AX25: 0.7521875 | AY25: 0.7712875 | AZ25: 0.7903875 | BA25: 0.8094875 | BB25: 0.8285875 | BC25: 0.8476875 | BD25: 0.8667875 | BE25: 0.8858875 | BF25: 0.9049875 | BG25: 0.9240875 | BH25: 0.9431875 | BI25: 0.9622875 | BJ25: 0.9813875 | BK25: 1.0004875 | BL25: 1 | BM25: 1 | BN25: 1 | BO25: 1 | BP25: 1 | BQ25: 1 | BR25: 1 | BS25: 1 | BT25: 1 | BU25: 1 | BV25: 1 | BW25: 1 | BX25: 1 | BY25: 1 | BZ25: 1 | CA25: 1 | CB25: 1 | CC25: 1 | CD25: 1 | CE25: 1 | CF25: 1 | CG25: 1 | CH25: 1 | CI25: 1 | CJ25: 1 | CK25: 1 | CL25: 1 | CM25: 1 | CN25: 1 | CO25: 1 | CP25: 1 | CQ25: 1 | CR25: 1 | CS25: 1 | CT25: 1 | CU25: 1 | CV25: 1 | CW25: 1 | CX25: 1 | CY25: 1 | CZ25: 1 | DA25: 1 | DB25: 1 | DC25: 1 | DD25: 1 | DE25: 1 | DF25: 1 | DG25: 1 | DH25: 1 | DI25: 1 | DJ25: 1 | DK25: 1 | DL25: 1 | DM25: 1 | DN25: 1 | DO25: 1 | DP25: 1 | DQ25: 1 | DR25: 1 | DS25: 1 | DT25: 1 | DU25: 1 | DV25: 1 | DW25: 1 | DX25: 1 | DY25: 1 | DZ25: 1 | EA25: 1 | EB25: 1 | EC25: 1 | ED25: 1 | EE25: 1 | EF25: 1 | EG25: 1 | EH25: 1 | EI25: 1 | EJ25: 1 | EK25: 1 | EL25: 1
D26: 1.3 Reparación envoltura metálica | F26: 183 | G26: 45489 | H26: 45782 | I26: =+SUM(I27:I33) -> 320 | J26: 0.1250084 | L26: =+SUMPRODUCT($J$27:$J$33,L27:L33) -> 0 | M26: =+SUMPRODUCT($J$27:$J$33,M27:M33) -> 0 | N26: =+SUMPRODUCT($J$27:$J$33,N27:N33) -> 0 | O26: =+SUMPRODUCT($J$27:$J$33,O27:O33) -> 0 | P26: =+SUMPRODUCT($J$27:$J$33,P27:P33) -> 0 | Q26: =+SUMPRODUCT($J$27:$J$33,Q27:Q33) -> 0 | R26: =+SUMPRODUCT($J$27:$J$33,R27:R33) -> 0.035 | S26: =+SUMPRODUCT($J$27:$J$33,S27:S33) -> 0.0730625 | ... EL26: =+SUMPRODUCT($J$27:$J$33,EL27:EL33) -> 1
E27: Procura de laminas acanaladas cerramientos exteriores | F27: 30 | G27: 45518 | H27: 45559 | I27: =+F27 -> 30 | J27: 0.05 | L27: 0 | M27: 0 | N27: 0 | O27: 0 | P27: 0 | Q27: 0 | R27: 0 | S27: 0 | T27: 0 | U27: 0 | V27: 0 | W27: 0 | X27: 0 | Y27: 0 | Z27: 0 | AA27: 0 | AB27: 0 | AC27: 1 | AD27: 1 | AE27: 1 | AF27: 1 | AG27: 1 | AH27: 1 | AI27: 1 | AJ27: 1 | AK27: 1 | AL27: 1 | AM27: 1 | AN27: 1 | AO27: 1 | AP27: 1 | AQ27: 1 | AR27: 1 | AS27: 1 | AT27: 1 | AU27: 1 | AV27: 1 | AW27: 1 | AX27: 1 | AY27: 1 | AZ27: 1 | BA27: 1 | BB27: 1 | BC27: 1 | BD27: 1 | BE27: 1 | BF27: 1 | BG27: 1 | BH27: 1 | BI27: 1 | BJ27: 1 | BK27: 1 | BL27: 1 | BM27: 1 | BN27: 1 | BO27: 1 | BP27: 1 | BQ27: 1 | BR27: 1 | BS27: 1 | BT27: 1 | BU27: 1 | BV27: 1 | BW27: 1 | BX27: 1 | BY27: 1 | BZ27: 1 | CA27: 1 | CB27: 1 | CC27: 1 | CD27: 1 | CE27: 1 | CF27: 1 | CG27: 1 | CH27: 1 | CI27: 1 | CJ27: 1 | CK27: 1 | CL27: 1 | CM27: 1 | CN27: 1 | CO27: 1 | CP27: 1 | CQ27: 1 | CR27: 1 | CS27: 1 | CT27: 1 | CU27: 1 | CV27: 1 | CW27: 1 | CX27: 1 | CY27: 1 | CZ27: 1 | DA27: 1 | DB27: 1 | DC27: 1 | DD27: 1 | DE27: 1 | DF27: 1 | DG27: 1 | DH27: 1 | DI27: 1 | DJ27: 1 | DK27: 1 | DL27: 1 | DM27: 1 | DN27: 1 | DO27: 1 | DP27: 1 | DQ27: 1 | DR27: 1 | DS27: 1 | DT27: 1 | DU27: 1 | DV27: 1 | DW27: 1 | DX27: 1 | DY27: 1 | DZ27: 1 | EA27: 1 | EB27: 1 | EC27: 1 | ED27: 1 | EE27: 1 | EF27: 1 | EG27: 1 | EH27: 1 | EI27: 1 | EJ27: 1 | EK27: 1 | EL27: 1
E28: Desmontaje de envoltura metálica externa en paredes | F28: 55 | G28: 45489 | H28: 45566 | I28: =+F28 -> 55 | J28: 0.21 | L28: 0 | M28: 0 | N28: 0 | O28: 0 | P28: 0 | Q28: 0 | R28: 0.1 | S28: 0.20875 | T28: 0.28155 | U28: 0.35435 | V28: 0.68874 | W28: 0.68874 | X28: 0.83634 | Y28: 0.88394 | Z28: 0.88394 | AA28: 0.88394 | AB28: 0.88394 | AC28: 0.88394 | AD28: 0.88394 | AE28: 0.91034 | AF28: 0.92786 | AG28: 0.92786 | AH28: 0.92786 | AI28: 0.92786 | AJ28: 0.97178 | AK28: 0.97178 | AL28: 0.97178 | AM28: 0.97178 | AN28: 0.97178 | AO28: 0.98178 | AP28: 0.98178 | AQ28: 0.98178 | AR28: 0.98178 | AS28: 0.98178 | AT28: 0.98178 | AU28: 0.98178 | AV28: 0.98788 | AW28: 0.99398 | AX28: 1.00008 | AY28: 1 | AZ28: 1 | BA28: 1 | BB28: 1 | BC28: 1 | BD28: 1 | BE28: 1 | BF28: 1 | BG28: 1 | BH28: 1 | BI28: 1 | BJ28: 1 | BK28: 1 | BL28: 1 | BM28: 1 | BN28: 1 | BO28: 1 | BP28: 1 | BQ28: 1 | BR28: 1 | BS28: 1 | BT28: 1 | BU28: 1 | BV28: 1 | BW28: 1 | BX28: 1 | BY28: 1 | BZ28: 1 | CA28: 1 | CB28: 1 | CC28: 1 | CD28: 1 | CE28: 1 | CF28: 1 | CG28: 1 | CH28: 1 | CI28: 1 | CJ28: 1 | CK28: 1 | CL28: 1 | CM28: 1 | CN28: 1 | CO28: 1 | CP28: 1 | CQ28: 1 | CR28: 1 | CS28: 1 | CT28: 1 | CU28: 1 | CV28: 1 | CW28: 1 | CX28: 1 | CY28: 1 | CZ28: 1 | DA28: 1 | DB28: 1 | DC28: 1 | DD28: 1 | DE28: 1 | DF28: 1 | DG28: 1 | DH28: 1 | DI28: 1 | DJ28: 1 | DK28: 1 | DL28: 1 | DM28: 1 | DN28: 1 | DO28: 1 | DP28: 1 | DQ28: 1 | DR28: 1 | DS28: 1 | DT28: 1 | DU28: 1 | DV28: 1 | DW28: 1 | DX28: 1 | DY28: 1 | DZ28: 1 | EA28: 1 | EB28: 1 | EC28: 1 | ED28: 1 | EE28: 1 | EF28: 1 | EG28: 1 | EH28: 1 | EI28: 1 | EJ28: 1 | EK28: 1 | EL28: 1
E29: Desmontaje de lana mineral | F29: 55 | G29: 45504 | H29: 45580 | I29: =+F29 -> 55 | J29: 0.14 | L29: 0 | M29: 0 | N29: 0 | O29: 0 | P29: 0 | Q29: 0 | R29: 0.1 | S29: 0.20875 | T29: 0.20875 | U29: 0.28155 | V29: 0.68874 | W29: 0.68874 | X29: 0.83634 | Y29: 0.88394 | Z29: 0.88394 | AA29: 0.88394 | AB29: 0.88394 | AC29: 0.88394 | AD29: 0.88394 | AE29: 0.91034 | AF29: 0.92786 | AG29: 0.92786 | AH29: 0.92786 | AI29: 0.92786 | AJ29: 0.958268 | AK29: 0.97178 | AL29: 0.97178 | AM29: 0.97178 | AN29: 0.97178 | AO29: 0.98178 | AP29: 0.98178 | AQ29: 0.98178 | AR29: 0.98178 | AS29: 0.98178 | AT29: 0.98178 | AU29: 0.98178 | AV29: 0.98788 | AW29: 0.99398 | AX29: 1.00008 | AY29: 1 | AZ29: 1 | BA29: 1 | BB29: 1 | BC29: 1 | BD29: 1 | BE29: 1 | BF29: 1 | BG29: 1 | BH29: 1 | BI29: 1 | BJ29: 1 | BK29: 1 | BL29: 1 | BM29: 1 | BN29: 1 | BO29: 1 | BP29: 1 | BQ29: 1 | BR29: 1 | BS29: 1 | BT29: 1 | BU29: 1 | BV29: 1 | BW29: 1 | BX29: 1 | BY29: 1 | BZ29: 1 | CA29: 1 | CB29: 1 | CC29: 1 | CD29: 1 | CE29: 1 | CF29: 1 | CG29: 1 | CH29: 1 | CI29: 1 | CJ29: 1 | CK29: 1 | CL29: 1 | CM29: 1 | CN29: 1 | CO29: 1 | CP29: 1 | CQ29: 1 | CR29: 1 | CS29: 1 | CT29: 1 | CU29: 1 | CV29: 1 | CW29: 1 | CX29: 1 | CY29: 1 | CZ29: 1 | DA29: 1 | DB29: 1 | DC29: 1 | DD29: 1 | DE29: 1 | DF29: 1 | DG29: 1 | DH29: 1 | DI29: 1 | DJ29: 1 | DK29: 1 | DL29: 1 | DM29: 1 | DN29: 1 | DO29: 1 | DP29: 1 | DQ29: 1 | DR29: 1 | DS29: 1 | DT29: 1 | DU29: 1 | DV29: 1 | DW29: 1 | DX29: 1 | DY29: 1 | DZ29: 1 | EA29: 1 | EB29: 1 | EC29: 1 | ED29: 1 | EE29: 1 | EF29: 1 | EG29: 1 | EH29: 1 | EI29: 1 | EJ29: 1 | EK29: 1 | EL29: 1
E30: Montaje y ajuste de envoltura metálica externa en paredes | F30: 40 | G30: 45670 | H30: 45727 | I30: =+F30 -> 40 | J30: 0.3 | L30: 0 | M30: 0 | N30: 0 | O30: 0 | P30: 0 | Q30: 0 | R30: 0 | S30: 0 | T30: 0 | U30: 0 | V30: 0 | W30: 0 | X30: 0 | Y30: 0 | Z30: 0 | AA30: 0 | AB30: 0 | AC30: 0 | AD30: 0 | AE30: 0 | AF30: 0 | AG30: 0 | AH30: 0 | AI30: 0 | AJ30: 0 | AK30: 0 | AL30: 0 | AM30: 0 | AN30: 0 | AO30: 0 | AP30: 0 | AQ30: 0 | AR30: 0 | AS30: 0 | AT30: 0 | AU30: 0 | AV30: 0 | AW30: 0 | AX30: 0 | AY30: 0 | AZ30: 0 | BA30: 0 | BB30: 0.1111 | BC30: 0.2222 | BD30: 0.3333 | BE30: 0.4444 | BF30: 0.5555 | BG30: 0.6666 | BH30: 0.7777 | BI30: 0.8888 | BJ30: 0.9999 | BK30: 1 | BL30: 1 | BM30: 1 | BN30: 1 | BO30: 1 | BP30: 1 | BQ30: 1 | BR30: 1 | BS30: 1 | BT30: 1 | BU30: 1 | BV30: 1 | BW30: 1 | BX30: 1 | BY30: 1 | BZ30: 1 | CA30: 1 | CB30: 1 | CC30: 1 | CD30: 1 | CE30: 1 | CF30: 1 | CG30: 1 | CH30: 1 | CI30: 1 | CJ30: 1 | CK30: 1 | CL30: 1 | CM30: 1 | CN30: 1 | CO30: 1 | CP30: 1 | CQ30: 1 | CR30: 1 | CS30: 1 | CT30: 1 | CU30: 1 | CV30: 1 | CW30: 1 | CX30: 1 | CY30: 1 | CZ30: 1 | DA30: 1 | DB30: 1 | DC30: 1 | DD30: 1 | DE30: 1 | DF30: 1 | DG30: 1 | DH30: 1 | DI30: 1 | DJ30: 1 | DK30: 1 | DL30: 1 | DM30: 1 | DN30: 1 | DO30: 1 | DP30: 1 | DQ30: 1 | DR30: 1 | DS30: 1 | DT30: 1 | DU30: 1 | DV30: 1 | DW30: 1 | DX30: 1 | DY30: 1 | DZ30: 1 | EA30: 1 | EB30: 1 | EC30: 1 | ED30: 1 | EE30: 1 | EF30: 1 | EG30: 1 | EH30: 1 | EI30: 1 | EJ30: 1 | EK30: 1 | EL30: 1
E31: Aplicación sistema de recubrimiento a envoltura metálica | F31: 55 | G31: 45698 | H31: 45782 | I31: =+F31 -> 55 | J31: 0.1 | L31: 0 | M31: 0 | N31: 0 | O31: 0 | P31: 0 | Q31: 0 | R31: 0 | S31: 0 | T31: 0 | U31: 0 | V31: 0 | W31: 0 | X31: 0 | Y31: 0 | Z31: 0 | AA31: 0 | AB31: 0 | AC31: 0 | AD31: 0 | AE31: 0 | AF31: 0 | AG31: 0 | AH31: 0 | AI31: 0 | AJ31: 0 | AK31: 0 | AL31: 0 | AM31: 0 | AN31: 0 | AO31: 0 | AP31: 0 | AQ31: 0 | AR31: 0 | AS31: 0 | AT31: 0 | AU31: 0 | AV31: 0 | AW31: 0 | AX31: 0 | AY31: 0 | AZ31: 0 | BA31: 0 | BB31: 0 | BC31: 0 | BD31: 0 | BE31: 0 | BF31: 0.1429 | BG31: 0.2858 | BH31: 0.4287 | BI31: 0.5716 | BJ31: 0.7145 | BK31: 0.8574 | BL31: 1.0003 | BM31: 1 | BN31: 1 | BO31: 1 | BP31: 1 | BQ31: 1 | BR31: 1 | BS31: 1 | BT31: 1 | BU31: 1 | BV31: 1 | BW31: 1 | BX31: 1 | BY31: 1 | BZ31: 1 | CA31: 1 | CB31: 1 | CC31: 1 | CD31: 1 | CE31: 1 | CF31: 1 | CG31: 1 | CH31: 1 | CI31: 1 | CJ31: 1 | CK31: 1 | CL31: 1 | CM31: 1 | CN31: 1 | CO31: 1 | CP31: 1 | CQ31: 1 | CR31: 1 | CS31: 1 | CT31: 1 | CU31: 1 | CV31: 1 | CW31: 1 | CX31: 1 | CY31: 1 | CZ31: 1 | DA31: 1 | DB31: 1 | DC31: 1 | DD31: 1 | DE31: 1 | DF31: 1 | DG31: 1 | DH31: 1 | DI31: 1 | DJ31: 1 | DK31: 1 | DL31: 1 | DM31: 1 | DN31: 1 | DO31: 1 | DP31: 1 | DQ31: 1 | DR31: 1 | DS31: 1 | DT31: 1 | DU31: 1 | DV31: 1 | DW31: 1 | DX31: 1 | DY31: 1 | DZ31: 1 | EA31: 1 | EB31: 1 | EC31: 1 | ED31: 1 | EE31: 1 | EF31: 1 | EG31: 1 | EH31: 1 | EI31: 1 | EJ31: 1 | EK31: 1 | EL31: 1
E32: Reemplazo de laminas acanaladas del piso N° 3. Techo de quemadores, lado este y oeste y techo de ventiladores | F32: 55 | G32: 45602 | H32: 45706 | I32: =+F32 -> 55 | J32: 0.1 | L32: 0 | M32: 0 | N32: 0 | O32: 0 | P32: 0 | Q32: 0 | R32: 0 | S32: 0 | T32: 0 | U32: 0 | V32: 0 | W32: 0 | X32: 0 | Y32: 0 | Z32: 0 | AA32: 0 | AB32: 0.48628333 | AC32: 1 | AD32: 1 | AE32: 1 | AF32: 1 | AG32: 1 | AH32: 1 | AI32: 1 | AJ32: 1 | AK32: 1 | AL32: 1 | AM32: 1 | AN32: 1 | AO32: 1 | AP32: 1 | AQ32: 1 | AR32: 1 | AS32: 1 | AT32: 1 | AU32: 1 | AV32: 1 | AW32: 1 | AX32: 1 | AY32: 1 | AZ32: 1 | BA32: 1 | BB32: 1 | BC32: 1 | BD32: 1 | BE32: 1 | BF32: 1 | BG32: 1 | BH32: 1 | BI32: 1 | BJ32: 1 | BK32: 1 | BL32: 1 | BM32: 1 | BN32: 1 | BO32: 1 | BP32: 1 | BQ32: 1 | BR32: 1 | BS32: 1 | BT32: 1 | BU32: 1 | BV32: 1 | BW32: 1 | BX32: 1 | BY32: 1 | BZ32: 1 | CA32: 1 | CB32: 1 | CC32: 1 | CD32: 1 | CE32: 1 | CF32: 1 | CG32: 1 | CH32: 1 | CI32: 1 | CJ32: 1 | CK32: 1 | CL32: 1 | CM32: 1 | CN32: 1 | CO32: 1 | CP32: 1 | CQ32: 1 | CR32: 1 | CS32: 1 | CT32: 1 | CU32: 1 | CV32: 1 | CW32: 1 | CX32: 1 | CY32: 1 | CZ32: 1 | DA32: 1 | DB32: 1 | DC32: 1 | DD32: 1 | DE32: 1 | DF32: 1 | DG32: 1 | DH32: 1 | DI32: 1 | DJ32: 1 | DK32: 1 | DL32: 1 | DM32: 1 | DN32: 1 | DO32: 1 | DP32: 1 | DQ32: 1 | DR32: 1 | DS32: 1 | DT32: 1 | DU32: 1 | DV32: 1 | DW32: 1 | DX32: 1 | DY32: 1 | DZ32: 1 | EA32: 1 | EB32: 1 | EC32: 1 | ED32: 1 | EE32: 1 | EF32: 1 | EG32: 1 | EH32: 1 | EI32: 1 | EJ32: 1 | EK32: 1 | EL32: 1
E33: Instalación de laminas de acero estriadas de 1/8" en piso Nº 3 lado este y oeste | F33: 30 | G33: 45581 | H33: 45622 | I33: =+F33 -> 30 | J33: 0.1 | L33: 0 | M33: 0 | N33: 0 | O33: 0 | P33: 0 | Q33: 0 | R33: 0 | S33: 0 | T33: 0 | U33: 0 | V33: 1 | W33: 1 | X33: 1 | Y33: 1 | Z33: 1 | AA33: 1 | AB33: 1 | AC33: 1 | AD33: 1 | AE33: 1 | AF33: 1 | AG33: 1 | AH33: 1 | AI33: 1 | AJ33: 1 | AK33: 1 | AL33: 1 | AM33: 1 | AN33: 1 | AO33: 1 | AP33: 1 | AQ33: 1 | AR33: 1 | AS33: 1 | AT33: 1 | AU33: 1 | AV33: 1 | AW33: 1 | AX33: 1 | AY33: 1 | AZ33: 1 | BA33: 1 | BB33: 1 | BC33: 1 | BD33: 1 | BE33: 1 | BF33: 1 | BG33: 1 | BH33: 1 | BI33: 1 | BJ33: 1 | BK33: 1 | BL33: 1 | BM33: 1 | BN33: 1 | BO33: 1 | BP33: 1 | BQ33: 1 | BR33: 1 | BS33: 1 | BT33: 1 | BU33: 1 | BV33: 1 | BW33: 1 | BX33: 1 | BY33: 1 | BZ33: 1 | CA33: 1 | CB33: 1 | CC33: 1 | CD33: 1 | CE33: 1 | CF33: 1 | CG33: 1 | CH33: 1 | CI33: 1 | CJ33: 1 | CK33: 1 | CL33: 1 | CM33: 1 | CN33: 1 | CO33: 1 | CP33: 1 | CQ33: 1 | CR33: 1 | CS33: 1 | CT33: 1 | CU33: 1 | CV33: 1 | CW33: 1 | CX33: 1 | CY33: 1 | CZ33: 1 | DA33: 1 | DB33: 1 | DC33: 1 | DD33: 1 | DE33: 1 | DF33: 1 | DG33: 1 | DH33: 1 | DI33: 1 | DJ33: 1 | DK33: 1 | DL33: 1 | DM33: 1 | DN33: 1 | DO33: 1 | DP33: 1 | DQ33: 1 | DR33: 1 | DS33: 1 | DT33: 1 | DU33: 1 | DV33: 1 | DW33: 1 | DX33: 1 | DY33: 1 | DZ33: 1 | EA33: 1 | EB33: 1 | EC33: 1 | ED33: 1 | EE33: 1 | EF33: 1 | EG33: 1 | EH33: 1 | EI33: 1 | EJ33: 1 | EK33: 1 | EL33: 1
D34: 1.4 Reparación de cámaras muertas | F34: 75 | G34: 45607 | H34: 45741 | I34: =+SUM(I35:I37) -> 75 | J34: 0.07022068 | L34: =+SUMPRODUCT($J$35:$J$37,L35:L37) -> 0 | M34: =+SUMPRODUCT($J$35:$J$37,M35:M37) -> 0 | N34: =+SUMPRODUCT($J$35:$J$37,N35:N37) -> 0 | O34: =+SUMPRODUCT($J$35:$J$37,O35:O37) -> 0 | P34: =+SUMPRODUCT($J$35:$J$37,P35:P37) -> 0 | Q34: =+SUMPRODUCT($J$35:$J$37,Q35:Q37) -> 0 | R34: =+SUMPRODUCT($J$35:$J$37,R35:R37) -> 0 | S34: =+SUMPRODUCT($J$35:$J$37,S35:S37) -> 0.015 | ... EL34: =+SUMPRODUCT($J$35:$J$37,EL35:EL37) -> 1
E35: Reparación de cámara muerta superior | F35: 25 | G35: 45607 | H35: 45639 | I35: =+F35 -> 25 | J35: 0.4 | L35: 0 | M35: 0 | N35: 0 | O35: 0 | P35: 0 | Q35: 0 | R35: 0 | S35: 0 | T35: 0 | U35: 0 | V35: 0.0075 | W35: 0.015 | X35: 0.03 | Y35: 0.045 | Z35: 0.07 | AA35: 0.085 | AB35: 0.1 | AC35: 0.125 | AD35: 0.1625 | AE35: 0.167 | AF35: 0.17 | AG35: 0.183 | AH35: 0.186 | AI35: 0.195 | AJ35: 0.25455 | AK35: 0.2617 | AL35: 0.2617 | AM35: 0.2617 | AN35: 0.26261 | AO35: 0.2656 | AP35: 0.2656 | AQ35: 0.2656 | AR35: 0.2656 | AS35: 0.2656 | AT35: 0.2656 | AU35: 0.2656 | AV35: 0.3268 | AW35: 0.388 | AX35: 0.4492 | AY35: 0.5104 | AZ35: 0.5716 | BA35: 0.6328 | BB35: 0.694 | BC35: 0.7552 | BD35: 0.8164 | BE35: 0.8776 | BF35: 0.9388 | BG35: 1 | BH35: 1 | BI35: 1 | BJ35: 1 | BK35: 1 | BL35: 1 | BM35: 1 | BN35: 1 | BO35: 1 | BP35: 1 | BQ35: 1 | BR35: 1 | BS35: 1 | BT35: 1 | BU35: 1 | BV35: 1 | BW35: 1 | BX35: 1 | BY35: 1 | BZ35: 1 | CA35: 1 | CB35: 1 | CC35: 1 | CD35: 1 | CE35: 1 | CF35: 1 | CG35: 1 | CH35: 1 | CI35: 1 | CJ35: 1 | CK35: 1 | CL35: 1 | CM35: 1 | CN35: 1 | CO35: 1 | CP35: 1 | CQ35: 1 | CR35: 1 | CS35: 1 | CT35: 1 | CU35: 1 | CV35: 1 | CW35: 1 | CX35: 1 | CY35: 1 | CZ35: 1 | DA35: 1 | DB35: 1 | DC35: 1 | DD35: 1 | DE35: 1 | DF35: 1 | DG35: 1 | DH35: 1 | DI35: 1 | DJ35: 1 | DK35: 1 | DL35: 1 | DM35: 1 | DN35: 1 | DO35: 1 | DP35: 1 | DQ35: 1 | DR35: 1 | DS35: 1 | DT35: 1 | DU35: 1 | DV35: 1 | DW35: 1 | DX35: 1 | DY35: 1 | DZ35: 1 | EA35: 1 | EB35: 1 | EC35: 1 | ED35: 1 | EE35: 1 | EF35: 1 | EG35: 1 | EH35: 1 | EI35: 1 | EJ35: 1 | EK35: 1 | EL35: 1
E36: Reparación de cámara muerta intermedia | F36: 25 | G36: 45670 | H36: 45702 | I36: =+F36 -> 25 | J36: 0.4 | L36: 0 | M36: 0 | N36: 0 | O36: 0 | P36: 0 | Q36: 0 | R36: 0 | S36: 0 | T36: 0.075 | U36: 0.15 | V36: 0.25 | W36: 0.25 | X36: 0.25 | Y36: 0.25 | Z36: 0.25 | AA36: 0.25 | AB36: 0.25 | AC36: 0.25 | AD36: 0.25 | AE36: 0.25 | AF36: 0.25 | AG36: 0.25 | AH36: 0.25 | AI36: 0.25 | AJ36: 0.25 | AK36: 0.25 | AL36: 0.25 | AM36: 0.25 | AN36: 0.25 | AO36: 0.25 | AP36: 0.25 | AQ36: 0.25 | AR36: 0.25 | AS36: 0.25 | AT36: 0.25 | AU36: 0.25 | AV36: 0.3 | AW36: 0.35 | AX36: 0.4 | AY36: 0.45 | AZ36: 0.5 | BA36: 0.55 | BB36: 0.6 | BC36: 0.65 | BD36: 0.7 | BE36: 0.75 | BF36: 0.8 | BG36: 0.85 | BH36: 0.9 | BI36: 0.95 | BJ36: 1 | BK36: 1 | BL36: 1 | BM36: 1 | BN36: 1 | BO36: 1 | BP36: 1 | BQ36: 1 | BR36: 1 | BS36: 1 | BT36: 1 | BU36: 1 | BV36: 1 | BW36: 1 | BX36: 1 | BY36: 1 | BZ36: 1 | CA36: 1 | CB36: 1 | CC36: 1 | CD36: 1 | CE36: 1 | CF36: 1 | CG36: 1 | CH36: 1 | CI36: 1 | CJ36: 1 | CK36: 1 | CL36: 1 | CM36: 1 | CN36: 1 | CO36: 1 | CP36: 1 | CQ36: 1 | CR36: 1 | CS36: 1 | CT36: 1 | CU36: 1 | CV36: 1 | CW36: 1 | CX36: 1 | CY36: 1 | CZ36: 1 | DA36: 1 | DB36: 1 | DC36: 1 | DD36: 1 | DE36: 1 | DF36: 1 | DG36: 1 | DH36: 1 | DI36: 1 | DJ36: 1 | DK36: 1 | DL36: 1 | DM36: 1 | DN36: 1 | DO36: 1 | DP36: 1 | DQ36: 1 | DR36: 1 | DS36: 1 | DT36: 1 | DU36: 1 | DV36: 1 | DW36: 1 | DX36: 1 | DY36: 1 | DZ36: 1 | EA36: 1 | EB36: 1 | EC36: 1 | ED36: 1 | EE36: 1 | EF36: 1 | EG36: 1 | EH36: 1 | EI36: 1 | EJ36: 1 | EK36: 1 | EL36: 1
E37: Reparación de cámara muerta inferior | F37: 25 | G37: 45705 | H37: 45741 | I37: =+F37 -> 25 | J37: 0.2 | L37: 0 | M37: 0 | N37: 0 | O37: 0 | P37: 0 | Q37: 0 | R37: 0 | S37: 0.075 | T37: 0.25 | U37: 0.25 | V37: 0.3475 | W37: 0.3475 | X37: 0.3475 | Y37: 0.3475 | Z37: 0.3475 | AA37: 0.3475 | AB37: 0.3475 | AC37: 0.3475 | AD37: 0.420625 | AE37: 0.445 | AF37: 0.445 | AG37: 0.4515 | AH37: 0.453125 | AI37: 0.45475 | AJ37: 0.50675 | AK37: 0.52625 | AL37: 0.52625 | AM37: 0.52625 | AN37: 0.52625 | AO37: 0.52625 | AP37: 0.52625 | AQ37: 0.52625 | AR37: 0.52625 | AS37: 0.52625 | AT37: 0.52625 | AU37: 0.52625 | AV37: 0.52625 | AW37: 0.52625 | AX37: 0.57885 | AY37: 0.63145 | AZ37: 0.68405 | BA37: 0.73665 | BB37: 0.78925 | BC37: 0.84185 | BD37: 0.89445 | BE37: 0.94705 | BF37: 0.99965 | BG37: 1 | BH37: 1 | BI37: 1 | BJ37: 1 | BK37: 1 | BL37: 1 | BM37: 1 | BN37: 1 | BO37: 1 | BP37: 1 | BQ37: 1 | BR37: 1 | BS37: 1 | BT37: 1 | BU37: 1 | BV37: 1 | BW37: 1 | BX37: 1 | BY37: 1 | BZ37: 1 | CA37: 1 | CB37: 1 | CC37: 1 | CD37: 1 | CE37: 1 | CF37: 1 | CG37: 1 | CH37: 1 | CI37: 1 | CJ37: 1 | CK37: 1 | CL37: 1 | CM37: 1 | CN37: 1 | CO37: 1 | CP37: 1 | CQ37: 1 | CR37: 1 | CS37: 1 | CT37: 1 | CU37: 1 | CV37: 1 | CW37: 1 | CX37: 1 | CY37: 1 | CZ37: 1 | DA37: 1 | DB37: 1 | DC37: 1 | DD37: 1 | DE37: 1 | DF37: 1 | DG37: 1 | DH37: 1 | DI37: 1 | DJ37: 1 | DK37: 1 | DL37: 1 | DM37: 1 | DN37: 1 | DO37: 1 | DP37: 1 | DQ37: 1 | DR37: 1 | DS37: 1 | DT37: 1 | DU37: 1 | DV37: 1 | DW37: 1 | DX37: 1 | DY37: 1 | DZ37: 1 | EA37: 1 | EB37: 1 | EC37: 1 | ED37: 1 | EE37: 1 | EF37: 1 | EG37: 1 | EH37: 1 | EI37: 1 | EJ37: 1 | EK37: 1 | EL37: 1
D38: 1.5 Reparación ductos de aire y gas | F38: 90 | G38: 45574 | H38: 45729 | I38: =+SUM(I39:I40) -> 80 | J38: 0.20241067 | L38: =+SUMPRODUCT($J$39:$J$40,L39:L40) -> 0 | M38: =+SUMPRODUCT($J$39:$J$40,M39:M40) -> 0 | N38: =+SUMPRODUCT($J$39:$J$40,N39:N40) -> 0 | O38: =+SUMPRODUCT($J$39:$J$40,O39:O40) -> 0 | P38: =+SUMPRODUCT($J$39:$J$40,P39:P40) -> 0 | Q38: =+SUMPRODUCT($J$39:$J$40,Q39:Q40) -> 0 | R38: =+SUMPRODUCT($J$39:$J$40,R39:R40) -> 0 | S38: =+SUMPRODUCT($J$39:$J$40,S39:S40) -> 0 | ... EL38: =+SUMPRODUCT($J$39:$J$40,EL39:EL40) -> 1
E39: Reconstrucción de ductos de entrada de aire | F39: 40 | G39: 45672 | H39: 45729 | I39: =+F39 -> 40 | J39: 0.66666667 | L39: 0 | M39: 0 | N39: 0 | O39: 0 | P39: 0 | Q39: 0 | R39: 0 | S39: 0 | T39: 0 | U39: 0 | V39: 0 | W39: 0 | X39: 0 | Y39: 0 | Z39: 0 | AA39: 0 | AB39: 0 | AC39: 0 | AD39: 0 | AE39: 0 | AF39: 0 | AG39: 0 | AH39: 0 | AI39: 0 | AJ39: 0 | AK39: 0 | AL39: 0 | AM39: 0 | AN39: 0 | AO39: 0 | AP39: 0 | AQ39: 0 | AR39: 0 | AS39: 0 | AT39: 0 | AU39: 0 | AV39: 0 | AW39: 0 | AX39: 0 | AY39: 0 | AZ39: 0.1 | BA39: 0.2 | BB39: 0.3 | BC39: 0.4 | BD39: 0.5 | BE39: 0.6 | BF39: 0.7 | BG39: 0.8 | BH39: 0.9 | BI39: 1 | BJ39: 1 | BK39: 1 | BL39: 1 | BM39: 1 | BN39: 1 | BO39: 1 | BP39: 1 | BQ39: 1 | BR39: 1 | BS39: 1 | BT39: 1 | BU39: 1 | BV39: 1 | BW39: 1 | BX39: 1 | BY39: 1 | BZ39: 1 | CA39: 1 | CB39: 1 | CC39: 1 | CD39: 1 | CE39: 1 | CF39: 1 | CG39: 1 | CH39: 1 | CI39: 1 | CJ39: 1 | CK39: 1 | CL39: 1 | CM39: 1 | CN39: 1 | CO39: 1 | CP39: 1 | CQ39: 1 | CR39: 1 | CS39: 1 | CT39: 1 | CU39: 1 | CV39: 1 | CW39: 1 | CX39: 1 | CY39: 1 | CZ39: 1 | DA39: 1 | DB39: 1 | DC39: 1 | DD39: 1 | DE39: 1 | DF39: 1 | DG39: 1 | DH39: 1 | DI39: 1 | DJ39: 1 | DK39: 1 | DL39: 1 | DM39: 1 | DN39: 1 | DO39: 1 | DP39: 1 | DQ39: 1 | DR39: 1 | DS39: 1 | DT39: 1 | DU39: 1 | DV39: 1 | DW39: 1 | DX39: 1 | DY39: 1 | DZ39: 1 | EA39: 1 | EB39: 1 | EC39: 1 | ED39: 1 | EE39: 1 | EF39: 1 | EG39: 1 | EH39: 1 | EI39: 1 | EJ39: 1 | EK39: 1 | EL39: 1
E40: Reconstrucción de ductos aire caliente | F40: 40 | G40: 45574 | H40: 45629 | I40: =+F40 -> 40 | J40: 0.33333333 | L40: 0 | M40: 0 | N40: 0 | O40: 0 | P40: 0 | Q40: 0 | R40: 0 | S40: 0 | T40: 0 | U40: 0 | V40: 0 | W40: 0 | X40: 0 | Y40: 0 | Z40: 0 | AA40: 0 | AB40: 0.0826815 | AC40: 0.2071382 | AD40: 0.2727413 | AE40: 0.301383 | AF40: 0.3511604 | AG40: 0.3879753 | AH40: 0.4778035 | AI40: 0.48433268 | AJ40: 0.49240073 | AK40: 0.49240073 | AL40: 0.49240073 | AM40: 0.49240073 | AN40: 0.49240073 | AO40: 0.49511936 | AP40: 0.53391936 | AQ40: 0.57271936 | AR40: 0.61151936 | AS40: 0.65031936 | AT40: 0.68911936 | AU40: 0.72791936 | AV40: 0.76671936 | AW40: 0.80551936 | AX40: 0.84431936 | AY40: 0.88311936 | AZ40: 0.92191936 | BA40: 0.96071936 | BB40: 0.99951936 | BC40: 1 | BD40: 1 | BE40: 1 | BF40: 1 | BG40: 1 | BH40: 1 | BI40: 1 | BJ40: 1 | BK40: 1 | BL40: 1 | BM40: 1 | BN40: 1 | BO40: 1 | BP40: 1 | BQ40: 1 | BR40: 1 | BS40: 1 | BT40: 1 | BU40: 1 | BV40: 1 | BW40: 1 | BX40: 1 | BY40: 1 | BZ40: 1 | CA40: 1 | CB40: 1 | CC40: 1 | CD40: 1 | CE40: 1 | CF40: 1 | CG40: 1 | CH40: 1 | CI40: 1 | CJ40: 1 | CK40: 1 | CL40: 1 | CM40: 1 | CN40: 1 | CO40: 1 | CP40: 1 | CQ40: 1 | CR40: 1 | CS40: 1 | CT40: 1 | CU40: 1 | CV40: 1 | CW40: 1 | CX40: 1 | CY40: 1 | CZ40: 1 | DA40: 1 | DB40: 1 | DC40: 1 | DD40: 1 | DE40: 1 | DF40: 1 | DG40: 1 | DH40: 1 | DI40: 1 | DJ40: 1 | DK40: 1 | DL40: 1 | DM40: 1 | DN40: 1 | DO40: 1 | DP40: 1 | DQ40: 1 | DR40: 1 | DS40: 1 | DT40: 1 | DU40: 1 | DV40: 1 | DW40: 1 | DX40: 1 | DY40: 1 | DZ40: 1 | EA40: 1 | EB40: 1 | EC40: 1 | ED40: 1 | EE40: 1 | EF40: 1 | EG40: 1 | EH40: 1 | EI40: 1 | EJ40: 1 | EK40: 1 | EL40: 1
